<?xml version="1.0"?>
<sdf version="1.5"><model name="gen__1907"><pose>0.000000e+00 0.000000e+00 2.250000e-02 0.000000e+00 -0.000000e+00 0.000000e+00</pose>
<link name="link_component_node-0__box"><pose>9.134731e-03 -1.152210e-02 -3.853100e-18 0.000000e+00 -0.000000e+00 0.000000e+00</pose>
<visual name="component_node-0__box_visual"><pose>-9.134731e-03 1.152210e-02 3.853100e-18 0.000000e+00 -0.000000e+00 0.000000e+00</pose>
<material><ambient>0.36 0.21 0.81 1.00</ambient><diffuse>0.36 0.21 0.81 1.00</diffuse><specular>0.1 0.1 0.1 1.00</specular></material>
<geometry><mesh><uri>model://rg_robot/meshes/CoreComponent.dae</uri></mesh></geometry></visual>
<collision name="component_node-0__box_collision"><pose>-9.134731e-03 1.152210e-02 3.853100e-18 0.000000e+00 -0.000000e+00 0.000000e+00</pose>
<surface><contact><ode><kd>3.333333e+06</kd><kp>9.000000e+04</kp></ode></contact>
<friction><ode><mu>1.000000e+00</mu>
<mu2>1.000000e+00</mu2>
<slip1>1.000000e-02</slip1>
<slip2>1.000000e-02</slip2></ode>
<bullet><friction>1.000000e+00</friction>
<friction2>1.000000e+00</friction2></bullet></friction></surface>
<geometry><box><size>9.000000e-02 9.000000e-02 4.500000e-02</size></box></geometry></collision>
<sensor type="imu" name="node-0-imu_sensor"><pose>-9.134731e-03 1.152210e-02 3.853100e-18 0.000000e+00 -0.000000e+00 0.000000e+00</pose>
<update_rate>8.000000e+00</update_rate>
<always_on>1</always_on></sensor>
<collision name="component_node-1__tail_collision"><pose>-9.134731e-03 -3.422790e-02 3.811467e-18 -1.570796e+00 -5.551115e-17 1.570796e+00</pose>
<surface><contact><ode><kd>3.333333e+06</kd><kp>9.000000e+04</kp></ode></contact>
<friction><ode><mu>1.000000e+00</mu>
<mu2>1.000000e+00</mu2>
<slip1>1.000000e-02</slip1>
<slip2>1.000000e-02</slip2></ode>
<bullet><friction>1.000000e+00</friction>
<friction2>1.000000e+00</friction2></bullet></friction></surface>
<geometry><box><size>1.500000e-03 3.400000e-02 3.400000e-02</size></box></geometry></collision>
<visual name="component_node-1__servo_servo_visual"><pose>-9.134731e-03 -4.732790e-02 3.084270e-18 -1.570796e+00 -5.551115e-17 1.570796e+00</pose>
<material><ambient>0.36 0.21 0.81 1.00</ambient><diffuse>0.36 0.21 0.81 1.00</diffuse><specular>0.1 0.1 0.1 1.00</specular></material>
<geometry><mesh><uri>model://rg_robot/meshes/ActiveCardanHinge_Servo_Holder.dae</uri></mesh></geometry></visual>
<collision name="component_node-1__servo_collision"><pose>-9.134731e-03 -4.732790e-02 3.084270e-18 -1.570796e+00 -5.551115e-17 1.570796e+00</pose>
<surface><contact><ode><kd>3.333333e+06</kd><kp>9.000000e+04</kp></ode></contact>
<friction><ode><mu>1.000000e+00</mu>
<mu2>1.000000e+00</mu2>
<slip1>1.000000e-02</slip1>
<slip2>1.000000e-02</slip2></ode>
<bullet><friction>1.000000e+00</friction>
<friction2>1.000000e+00</friction2></bullet></friction></surface>
<geometry><box><size>2.450000e-02 3.400000e-02 1.000000e-02</size></box></geometry></collision>
<collision name="component_node-2__slot_a_collision"><pose>-9.134731e-03 5.727210e-02 3.853100e-18 3.141593e+00 -0.000000e+00 1.570796e+00</pose>
<surface><contact><ode><kd>3.333333e+06</kd><kp>9.000000e+04</kp></ode></contact>
<friction><ode><mu>1.000000e+00</mu>
<mu2>1.000000e+00</mu2>
<slip1>1.000000e-02</slip1>
<slip2>1.000000e-02</slip2></ode>
<bullet><friction>1.000000e+00</friction>
<friction2>1.000000e+00</friction2></bullet></friction></surface>
<geometry><box><size>1.500000e-03 3.400000e-02 3.400000e-02</size></box></geometry></collision>
<visual name="component_node-2__conn_a_conn_a_visual"><pose>-9.134731e-03 6.762210e-02 3.853100e-18 3.141593e+00 -0.000000e+00 1.570796e+00</pose>
<material><ambient>0.36 0.21 0.81 1.00</ambient><diffuse>0.36 0.21 0.81 1.00</diffuse><specular>0.1 0.1 0.1 1.00</specular></material>
<geometry><mesh><uri>model://rg_robot/meshes/PassiveHinge.dae</uri></mesh></geometry></visual>
<collision name="component_node-2__conn_a_collision"><pose>-9.134731e-03 6.837210e-02 3.853100e-18 3.141593e+00 -0.000000e+00 1.570796e+00</pose>
<surface><contact><ode><kd>3.333333e+06</kd><kp>9.000000e+04</kp></ode></contact>
<friction><ode><mu>1.000000e+00</mu>
<mu2>1.000000e+00</mu2>
<slip1>1.000000e-02</slip1>
<slip2>1.000000e-02</slip2></ode>
<bullet><friction>1.000000e+00</friction>
<friction2>1.000000e+00</friction2></bullet></friction></surface>
<geometry><box><size>2.050000e-02 2.000000e-03 2.000000e-02</size></box></geometry></collision>
<visual name="component_node-5__tail_visual"><pose>3.661527e-02 1.152210e-02 3.780415e-18 1.570796e+00 -1.570092e-16 -3.141593e+00</pose>
<material><ambient>0.36 0.21 0.81 1.00</ambient><diffuse>0.36 0.21 0.81 1.00</diffuse><specular>0.1 0.1 0.1 1.00</specular></material>
<geometry><box><size>1.500000e-03 3.400000e-02 3.400000e-02</size></box></geometry></visual>
<collision name="component_node-5__tail_collision"><pose>3.661527e-02 1.152210e-02 3.780415e-18 1.570796e+00 -1.570092e-16 -3.141593e+00</pose>
<surface><contact><ode><kd>3.333333e+06</kd><kp>9.000000e+04</kp></ode></contact>
<friction><ode><mu>1.000000e+00</mu>
<mu2>1.000000e+00</mu2>
<slip1>1.000000e-02</slip1>
<slip2>1.000000e-02</slip2></ode>
<bullet><friction>1.000000e+00</friction>
<friction2>1.000000e+00</friction2></bullet></friction></surface>
<geometry><box><size>1.500000e-03 3.400000e-02 3.400000e-02</size></box></geometry></collision>
<visual name="component_node-5__connection_visual"><pose>5.715031e-02 -1.051569e-02 -1.126869e-17 1.570796e+00 -4.440892e-16 2.320911e+00</pose>
<material><ambient>0.36 0.21 0.81 1.00</ambient><diffuse>0.36 0.21 0.81 1.00</diffuse><specular>0.1 0.1 0.1 1.00</specular></material>
<geometry><box><size>5.874458e-02 2.000000e-02 2.000000e-03</size></box></geometry></visual>
<collision name="component_node-5__connection_collision"><pose>5.715031e-02 -1.051569e-02 -1.126869e-17 1.570796e+00 -4.440892e-16 2.320911e+00</pose>
<surface><contact><ode><kd>3.333333e+06</kd><kp>9.000000e+04</kp></ode></contact>
<friction><ode><mu>1.000000e+00</mu>
<mu2>1.000000e+00</mu2>
<slip1>1.000000e-02</slip1>
<slip2>1.000000e-02</slip2></ode>
<bullet><friction>1.000000e+00</friction>
<friction2>1.000000e+00</friction2></bullet></friction></surface>
<geometry><box><size>5.874458e-02 2.000000e-02 2.000000e-03</size></box></geometry></collision>
<visual name="component_node-5__root_visual"><pose>7.768536e-02 -3.255348e-02 -2.631780e-17 1.570796e+00 -4.440892e-16 2.320911e+00</pose>
<material><ambient>0.36 0.21 0.81 1.00</ambient><diffuse>0.36 0.21 0.81 1.00</diffuse><specular>0.1 0.1 0.1 1.00</specular></material>
<geometry><box><size>1.500000e-03 3.400000e-02 3.400000e-02</size></box></geometry></visual>
<collision name="component_node-5__root_collision"><pose>7.768536e-02 -3.255348e-02 -2.631780e-17 1.570796e+00 -4.440892e-16 2.320911e+00</pose>
<surface><contact><ode><kd>3.333333e+06</kd><kp>9.000000e+04</kp></ode></contact>
<friction><ode><mu>1.000000e+00</mu>
<mu2>1.000000e+00</mu2>
<slip1>1.000000e-02</slip1>
<slip2>1.000000e-02</slip2></ode>
<bullet><friction>1.000000e+00</friction>
<friction2>1.000000e+00</friction2></bullet></friction></surface>
<geometry><box><size>1.500000e-03 3.400000e-02 3.400000e-02</size></box></geometry></collision>
<collision name="component_node-6__tail_collision"><pose>7.870794e-02 -3.365090e-02 -2.660923e-17 1.570796e+00 5.551115e-17 2.320911e+00</pose>
<surface><contact><ode><kd>3.333333e+06</kd><kp>9.000000e+04</kp></ode></contact>
<friction><ode><mu>1.000000e+00</mu>
<mu2>1.000000e+00</mu2>
<slip1>1.000000e-02</slip1>
<slip2>1.000000e-02</slip2></ode>
<bullet><friction>1.000000e+00</friction>
<friction2>1.000000e+00</friction2></bullet></friction></surface>
<geometry><box><size>1.500000e-03 3.400000e-02 3.400000e-02</size></box></geometry></collision>
<visual name="component_node-6__servo_servo_visual"><pose>8.763851e-02 -4.323500e-02 -2.515484e-17 1.570796e+00 5.551115e-17 2.320911e+00</pose>
<material><ambient>0.36 0.21 0.81 1.00</ambient><diffuse>0.36 0.21 0.81 1.00</diffuse><specular>0.1 0.1 0.1 1.00</specular></material>
<geometry><mesh><uri>model://rg_robot/meshes/ActiveCardanHinge_Servo_Holder.dae</uri></mesh></geometry></visual>
<collision name="component_node-6__servo_collision"><pose>8.763851e-02 -4.323500e-02 -2.515484e-17 1.570796e+00 5.551115e-17 2.320911e+00</pose>
<surface><contact><ode><kd>3.333333e+06</kd><kp>9.000000e+04</kp></ode></contact>
<friction><ode><mu>1.000000e+00</mu>
<mu2>1.000000e+00</mu2>
<slip1>1.000000e-02</slip1>
<slip2>1.000000e-02</slip2></ode>
<bullet><friction>1.000000e+00</friction>
<friction2>1.000000e+00</friction2></bullet></friction></surface>
<geometry><box><size>2.450000e-02 3.400000e-02 1.000000e-02</size></box></geometry></collision>
<visual name="component_node-16__box_touch_visual"><pose>-5.938473e-02 1.152210e-02 3.853100e-18 -1.570796e+00 -0.000000e+00 3.141593e+00</pose>
<material><ambient>0.36 0.21 0.81 1.00</ambient><diffuse>0.36 0.21 0.81 1.00</diffuse><specular>0.1 0.1 0.1 1.00</specular></material>
<geometry><mesh><uri>model://rg_robot/meshes/TouchSensor.dae</uri></mesh></geometry></visual>
<collision name="component_node-16__box_collision"><pose>-5.488473e-02 1.152210e-02 3.853100e-18 -1.570796e+00 -0.000000e+00 3.141593e+00</pose>
<surface><contact><ode><kd>3.333333e+06</kd><kp>9.000000e+04</kp></ode></contact>
<friction><ode><mu>1.000000e+00</mu>
<mu2>1.000000e+00</mu2>
<slip1>1.000000e-02</slip1>
<slip2>1.000000e-02</slip2></ode>
<bullet><friction>1.000000e+00</friction>
<friction2>1.000000e+00</friction2></bullet></friction></surface>
<geometry><box><size>1.500000e-03 3.400000e-02 3.400000e-02</size></box></geometry></collision>
<collision name="component_node-16__left_collision"><pose>-6.013473e-02 1.152210e-02 1.025000e-02 -1.570796e+00 -0.000000e+00 3.141593e+00</pose>
<surface><contact><ode><kd>3.333333e+06</kd><kp>9.000000e+04</kp></ode></contact>
<friction><ode><mu>1.000000e+00</mu>
<mu2>1.000000e+00</mu2>
<slip1>1.000000e-02</slip1>
<slip2>1.000000e-02</slip2></ode>
<bullet><friction>1.000000e+00</friction>
<friction2>1.000000e+00</friction2></bullet></friction></surface>
<geometry><box><size>9.000000e-03 1.850000e-02 1.600000e-02</size></box></geometry></collision>
<sensor type="contact" name="node-16-left_sensor"><pose>-5.488473e-02 1.152210e-02 0.000000e+00 -1.570796e+00 -0.000000e+00 3.141593e+00</pose>
<contact><collision>component_node-16__left_collision</collision></contact>
<update_rate>8.000000e+00</update_rate>
<always_on>1</always_on></sensor>
<collision name="component_node-16__right_collision"><pose>-6.013473e-02 1.152210e-02 -1.025000e-02 -1.570796e+00 -0.000000e+00 3.141593e+00</pose>
<surface><contact><ode><kd>3.333333e+06</kd><kp>9.000000e+04</kp></ode></contact>
<friction><ode><mu>1.000000e+00</mu>
<mu2>1.000000e+00</mu2>
<slip1>1.000000e-02</slip1>
<slip2>1.000000e-02</slip2></ode>
<bullet><friction>1.000000e+00</friction>
<friction2>1.000000e+00</friction2></bullet></friction></surface>
<geometry><box><size>9.000000e-03 1.850000e-02 1.600000e-02</size></box></geometry></collision>
<sensor type="contact" name="node-16-right_sensor"><pose>-5.488473e-02 1.152210e-02 6.938894e-18 -1.570796e+00 -0.000000e+00 3.141593e+00</pose>
<contact><collision>component_node-16__right_collision</collision></contact>
<update_rate>8.000000e+00</update_rate>
<always_on>1</always_on></sensor>
<inertial><mass>1.371749e-01</mass><inertia><ixx>1.611953e-04</ixx><ixy>6.654490e-05</ixy><ixz>4.213989e-20</ixz><iyy>2.459035e-04</iyy><iyz>-2.054055e-20</iyz><izz>3.674618e-04</izz></inertia></inertial>
<self_collide>True</self_collide></link>
<link name="link_component_node-1__frame"><pose>-7.884479e-18 -8.050854e-02 -1.971120e-18 0.000000e+00 -0.000000e+00 0.000000e+00</pose>
<visual name="component_node-1__frame_frame_visual"><pose>1.867070e-18 8.408537e-03 4.667675e-19 -1.570796e+00 -5.551115e-17 1.570796e+00</pose>
<material><ambient>0.36 0.21 0.81 1.00</ambient><diffuse>0.36 0.21 0.81 1.00</diffuse><specular>0.1 0.1 0.1 1.00</specular></material>
<geometry><mesh><uri>model://rg_robot/meshes/ActiveHinge_Frame.dae</uri></mesh></geometry></visual>
<collision name="component_node-1__frame_collision"><pose>1.867070e-18 8.408537e-03 4.667675e-19 -1.570796e+00 -5.551115e-17 1.570796e+00</pose>
<surface><contact><ode><kd>3.333333e+06</kd><kp>9.000000e+04</kp></ode></contact>
<friction><ode><mu>1.000000e+00</mu>
<mu2>1.000000e+00</mu2>
<slip1>1.000000e-02</slip1>
<slip2>1.000000e-02</slip2></ode>
<bullet><friction>1.000000e+00</friction>
<friction2>1.000000e+00</friction2></bullet></friction></surface>
<geometry><box><size>1.800000e-02 3.400000e-02 1.000000e-02</size></box></geometry></collision>
<visual name="component_node-1__root_visual"><pose>-3.200692e-19 -1.441463e-03 -8.001729e-20 -1.570796e+00 -5.551115e-17 1.570796e+00</pose>
<material><ambient>0.36 0.21 0.81 1.00</ambient><diffuse>0.36 0.21 0.81 1.00</diffuse><specular>0.1 0.1 0.1 1.00</specular></material>
<geometry><box><size>1.500000e-03 3.400000e-02 3.400000e-02</size></box></geometry></visual>
<collision name="component_node-1__root_collision"><pose>-3.200692e-19 -1.441463e-03 -8.001729e-20 -1.570796e+00 -5.551115e-17 1.570796e+00</pose>
<surface><contact><ode><kd>3.333333e+06</kd><kp>9.000000e+04</kp></ode></contact>
<friction><ode><mu>1.000000e+00</mu>
<mu2>1.000000e+00</mu2>
<slip1>1.000000e-02</slip1>
<slip2>1.000000e-02</slip2></ode>
<bullet><friction>1.000000e+00</friction>
<friction2>1.000000e+00</friction2></bullet></friction></surface>
<geometry><box><size>1.500000e-03 3.400000e-02 3.400000e-02</size></box></geometry></collision>
<inertial><mass>8.200000e-03</mass><inertia><ixx>9.230347e-07</ixx><ixy>3.510057e-22</ixy><ixz>-2.344696e-22</ixz><iyy>1.474267e-06</iyy><iyz>-1.628363e-22</iyz><izz>8.174347e-07</izz></inertia></inertial>
<self_collide>True</self_collide></link>
<joint type="revolute" name="joint_link_component_node-0__box_link_component_node-1__frame"><pose>2.977293e-18 1.340854e-02 7.443233e-19 -1.570796e+00 -5.551115e-17 1.570796e+00</pose>
<parent>link_component_node-0__box</parent>
<child>link_component_node-1__frame</child>
<axis><xyz>0.000000e+00 1.000000e+00 0.000000e+00</xyz>
<use_parent_model_frame>0</use_parent_model_frame>
<limit><lower>-7.853982e-01</lower>
<upper>7.853982e-01</upper>
<effort>1.765800e-01</effort>
<velocity>5.235988e+00</velocity></limit></axis></joint>
<link name="link_component_node-2__conn_b"><pose>-3.972094e-34 9.133421e-02 8.372717e-19 0.000000e+00 -0.000000e+00 0.000000e+00</pose>
<visual name="component_node-2__conn_b_conn_b_visual"><pose>2.909139e-34 -1.798421e-02 -8.372717e-19 -3.486306e-32 -0.000000e+00 -1.570796e+00</pose>
<material><ambient>0.36 0.21 0.81 1.00</ambient><diffuse>0.36 0.21 0.81 1.00</diffuse><specular>0.1 0.1 0.1 1.00</specular></material>
<geometry><mesh><uri>model://rg_robot/meshes/PassiveHinge.dae</uri></mesh></geometry></visual>
<collision name="component_node-2__conn_b_collision"><pose>2.909139e-34 -1.798421e-02 -8.372717e-19 3.141593e+00 -0.000000e+00 1.570796e+00</pose>
<surface><contact><ode><kd>3.333333e+06</kd><kp>9.000000e+04</kp></ode></contact>
<friction><ode><mu>1.000000e+00</mu>
<mu2>1.000000e+00</mu2>
<slip1>1.000000e-02</slip1>
<slip2>1.000000e-02</slip2></ode>
<bullet><friction>1.000000e+00</friction>
<friction2>1.000000e+00</friction2></bullet></friction></surface>
<geometry><box><size>2.050000e-02 2.000000e-03 2.000000e-02</size></box></geometry></collision>
<collision name="component_node-2__slot_b_collision"><pose>2.492956e-34 -6.884211e-03 -8.372717e-19 3.141593e+00 -0.000000e+00 1.570796e+00</pose>
<surface><contact><ode><kd>3.333333e+06</kd><kp>9.000000e+04</kp></ode></contact>
<friction><ode><mu>1.000000e+00</mu>
<mu2>1.000000e+00</mu2>
<slip1>1.000000e-02</slip1>
<slip2>1.000000e-02</slip2></ode>
<bullet><friction>1.000000e+00</friction>
<friction2>1.000000e+00</friction2></bullet></friction></surface>
<geometry><box><size>1.500000e-03 3.400000e-02 3.400000e-02</size></box></geometry></collision>
<collision name="component_node-3__tail_collision"><pose>-4.934407e-35 -5.384211e-03 -7.454232e-19 1.224647e-16 1.224647e-16 -1.570796e+00</pose>
<surface><contact><ode><kd>3.333333e+06</kd><kp>9.000000e+04</kp></ode></contact>
<friction><ode><mu>1.000000e+00</mu>
<mu2>1.000000e+00</mu2>
<slip1>1.000000e-02</slip1>
<slip2>1.000000e-02</slip2></ode>
<bullet><friction>1.000000e+00</friction>
<friction2>1.000000e+00</friction2></bullet></friction></surface>
<geometry><box><size>1.500000e-03 3.400000e-02 3.400000e-02</size></box></geometry></collision>
<visual name="component_node-3__servo_servo_visual"><pose>-4.934407e-35 7.715789e-03 8.588641e-19 1.224647e-16 1.224647e-16 -1.570796e+00</pose>
<material><ambient>0.14 0.38 0.51 1.00</ambient><diffuse>0.14 0.38 0.51 1.00</diffuse><specular>0.1 0.1 0.1 1.00</specular></material>
<geometry><mesh><uri>model://rg_robot/meshes/ActiveCardanHinge_Servo_Holder.dae</uri></mesh></geometry></visual>
<collision name="component_node-3__servo_collision"><pose>-4.934407e-35 7.715789e-03 8.588641e-19 1.224647e-16 1.224647e-16 -1.570796e+00</pose>
<surface><contact><ode><kd>3.333333e+06</kd><kp>9.000000e+04</kp></ode></contact>
<friction><ode><mu>1.000000e+00</mu>
<mu2>1.000000e+00</mu2>
<slip1>1.000000e-02</slip1>
<slip2>1.000000e-02</slip2></ode>
<bullet><friction>1.000000e+00</friction>
<friction2>1.000000e+00</friction2></bullet></friction></surface>
<geometry><box><size>2.450000e-02 3.400000e-02 1.000000e-02</size></box></geometry></collision>
<inertial><mass>1.900000e-02</mass><inertia><ixx>2.619174e-06</ixx><ixy>3.756771e-38</ixy><ixz>-9.295069e-23</ixz><iyy>2.709667e-06</iyy><iyz>-7.784746e-23</iyz><izz>3.378174e-06</izz></inertia></inertial>
<self_collide>True</self_collide></link>
<link name="link_component_node-3__frame"><pose>-4.465535e-34 1.275252e-01 5.717865e-18 0.000000e+00 -0.000000e+00 0.000000e+00</pose>
<visual name="component_node-3__frame_frame_visual"><pose>0.000000e+00 -1.522521e-02 -2.399072e-18 1.224647e-16 1.224647e-16 -1.570796e+00</pose>
<material><ambient>0.14 0.38 0.51 1.00</ambient><diffuse>0.14 0.38 0.51 1.00</diffuse><specular>0.1 0.1 0.1 1.00</specular></material>
<geometry><mesh><uri>model://rg_robot/meshes/ActiveHinge_Frame.dae</uri></mesh></geometry></visual>
<collision name="component_node-3__frame_collision"><pose>0.000000e+00 -1.522521e-02 -2.399072e-18 1.224647e-16 1.224647e-16 -1.570796e+00</pose>
<surface><contact><ode><kd>3.333333e+06</kd><kp>9.000000e+04</kp></ode></contact>
<friction><ode><mu>1.000000e+00</mu>
<mu2>1.000000e+00</mu2>
<slip1>1.000000e-02</slip1>
<slip2>1.000000e-02</slip2></ode>
<bullet><friction>1.000000e+00</friction>
<friction2>1.000000e+00</friction2></bullet></friction></surface>
<geometry><box><size>1.800000e-02 3.400000e-02 1.000000e-02</size></box></geometry></collision>
<visual name="component_node-3__root_visual"><pose>0.000000e+00 -5.375207e-03 -1.192795e-18 1.224647e-16 1.224647e-16 -1.570796e+00</pose>
<material><ambient>0.14 0.38 0.51 1.00</ambient><diffuse>0.14 0.38 0.51 1.00</diffuse><specular>0.1 0.1 0.1 1.00</specular></material>
<geometry><box><size>1.500000e-03 3.400000e-02 3.400000e-02</size></box></geometry></visual>
<collision name="component_node-3__root_collision"><pose>0.000000e+00 -5.375207e-03 -1.192795e-18 1.224647e-16 1.224647e-16 -1.570796e+00</pose>
<surface><contact><ode><kd>3.333333e+06</kd><kp>9.000000e+04</kp></ode></contact>
<friction><ode><mu>1.000000e+00</mu>
<mu2>1.000000e+00</mu2>
<slip1>1.000000e-02</slip1>
<slip2>1.000000e-02</slip2></ode>
<bullet><friction>1.000000e+00</friction>
<friction2>1.000000e+00</friction2></bullet></friction></surface>
<geometry><box><size>1.500000e-03 3.400000e-02 3.400000e-02</size></box></geometry></collision>
<collision name="component_node-4__tail_collision"><pose>0.000000e+00 -3.875207e-03 -9.344130e-19 -1.570796e+00 1.110223e-16 -1.570796e+00</pose>
<surface><contact><ode><kd>3.333333e+06</kd><kp>9.000000e+04</kp></ode></contact>
<friction><ode><mu>1.000000e+00</mu>
<mu2>1.000000e+00</mu2>
<slip1>1.000000e-02</slip1>
<slip2>1.000000e-02</slip2></ode>
<bullet><friction>1.000000e+00</friction>
<friction2>1.000000e+00</friction2></bullet></friction></surface>
<geometry><box><size>1.500000e-03 3.400000e-02 3.400000e-02</size></box></geometry></collision>
<visual name="component_node-4__servo_servo_visual"><pose>0.000000e+00 9.224793e-03 1.974371e-18 -1.570796e+00 1.110223e-16 -1.570796e+00</pose>
<material><ambient>0.36 0.21 0.81 1.00</ambient><diffuse>0.36 0.21 0.81 1.00</diffuse><specular>0.1 0.1 0.1 1.00</specular></material>
<geometry><mesh><uri>model://rg_robot/meshes/ActiveCardanHinge_Servo_Holder.dae</uri></mesh></geometry></visual>
<collision name="component_node-4__servo_collision"><pose>0.000000e+00 9.224793e-03 1.974371e-18 -1.570796e+00 1.110223e-16 -1.570796e+00</pose>
<surface><contact><ode><kd>3.333333e+06</kd><kp>9.000000e+04</kp></ode></contact>
<friction><ode><mu>1.000000e+00</mu>
<mu2>1.000000e+00</mu2>
<slip1>1.000000e-02</slip1>
<slip2>1.000000e-02</slip2></ode>
<bullet><friction>1.000000e+00</friction>
<friction2>1.000000e+00</friction2></bullet></friction></surface>
<geometry><box><size>2.450000e-02 3.400000e-02 1.000000e-02</size></box></geometry></collision>
<inertial><mass>2.420000e-02</mass><inertia><ixx>4.062289e-06</ixx><ixy>5.086302e-22</ixy><ixz>-1.462516e-22</ixz><iyy>3.764933e-06</iyy><iyz>5.601507e-23</iyz><izz>3.375889e-06</izz></inertia></inertial>
<self_collide>True</self_collide></link>
<link name="link_component_node-4__frame"><pose>-4.465535e-34 1.584085e-01 1.250140e-17 0.000000e+00 -0.000000e+00 0.000000e+00</pose>
<visual name="component_node-4__frame_frame_visual"><pose>0.000000e+00 -8.408537e-03 -1.867070e-18 -1.570796e+00 1.110223e-16 -1.570796e+00</pose>
<material><ambient>0.36 0.21 0.81 1.00</ambient><diffuse>0.36 0.21 0.81 1.00</diffuse><specular>0.1 0.1 0.1 1.00</specular></material>
<geometry><mesh><uri>model://rg_robot/meshes/ActiveHinge_Frame.dae</uri></mesh></geometry></visual>
<collision name="component_node-4__frame_collision"><pose>0.000000e+00 -8.408537e-03 -1.867070e-18 -1.570796e+00 1.110223e-16 -1.570796e+00</pose>
<surface><contact><ode><kd>3.333333e+06</kd><kp>9.000000e+04</kp></ode></contact>
<friction><ode><mu>1.000000e+00</mu>
<mu2>1.000000e+00</mu2>
<slip1>1.000000e-02</slip1>
<slip2>1.000000e-02</slip2></ode>
<bullet><friction>1.000000e+00</friction>
<friction2>1.000000e+00</friction2></bullet></friction></surface>
<geometry><box><size>1.800000e-02 3.400000e-02 1.000000e-02</size></box></geometry></collision>
<visual name="component_node-4__root_visual"><pose>0.000000e+00 1.441463e-03 3.200692e-19 -1.570796e+00 1.110223e-16 -1.570796e+00</pose>
<material><ambient>0.36 0.21 0.81 1.00</ambient><diffuse>0.36 0.21 0.81 1.00</diffuse><specular>0.1 0.1 0.1 1.00</specular></material>
<geometry><box><size>1.500000e-03 3.400000e-02 3.400000e-02</size></box></geometry></visual>
<collision name="component_node-4__root_collision"><pose>0.000000e+00 1.441463e-03 3.200692e-19 -1.570796e+00 1.110223e-16 -1.570796e+00</pose>
<surface><contact><ode><kd>3.333333e+06</kd><kp>9.000000e+04</kp></ode></contact>
<friction><ode><mu>1.000000e+00</mu>
<mu2>1.000000e+00</mu2>
<slip1>1.000000e-02</slip1>
<slip2>1.000000e-02</slip2></ode>
<bullet><friction>1.000000e+00</friction>
<friction2>1.000000e+00</friction2></bullet></friction></surface>
<geometry><box><size>1.500000e-03 3.400000e-02 3.400000e-02</size></box></geometry></collision>
<inertial><mass>8.200000e-03</mass><inertia><ixx>9.230347e-07</ixx><ixy>3.273530e-22</ixy><ixz>-7.971910e-23</ixz><iyy>1.474267e-06</iyy><iyz>1.416077e-22</iyz><izz>8.174347e-07</izz></inertia></inertial>
<self_collide>True</self_collide></link>
<joint type="revolute" name="joint_link_component_node-3__frame_link_component_node-4__frame"><pose>0.000000e+00 -1.340854e-02 -2.977293e-18 -1.570796e+00 2.220446e-16 -1.570796e+00</pose>
<parent>link_component_node-3__frame</parent>
<child>link_component_node-4__frame</child>
<axis><xyz>0.000000e+00 1.000000e+00 0.000000e+00</xyz>
<use_parent_model_frame>0</use_parent_model_frame>
<limit><lower>-7.853982e-01</lower>
<upper>7.853982e-01</upper>
<effort>1.765800e-01</effort>
<velocity>5.235988e+00</velocity></limit></axis></joint>
<joint type="revolute" name="joint_link_component_node-2__conn_b_link_component_node-3__frame"><pose>0.000000e+00 -2.022521e-02 -3.011395e-18 1.224647e-16 1.224647e-16 -1.570796e+00</pose>
<parent>link_component_node-2__conn_b</parent>
<child>link_component_node-3__frame</child>
<axis><xyz>0.000000e+00 1.000000e+00 0.000000e+00</xyz>
<use_parent_model_frame>0</use_parent_model_frame>
<limit><lower>-7.853982e-01</lower>
<upper>7.853982e-01</upper>
<effort>1.765800e-01</effort>
<velocity>5.235988e+00</velocity></limit></axis></joint>
<joint type="revolute" name="joint_link_component_node-0__box_link_component_node-2__conn_b"><pose>3.218465e-34 -2.623421e-02 -8.372717e-19 3.141593e+00 -0.000000e+00 1.570796e+00</pose>
<parent>link_component_node-0__box</parent>
<child>link_component_node-2__conn_b</child>
<axis><xyz>0.000000e+00 0.000000e+00 1.000000e+00</xyz>
<use_parent_model_frame>0</use_parent_model_frame>
<limit><lower>-1.047198e+00</lower>
<upper>1.047198e+00</upper></limit></axis></joint>
<link name="link_component_node-6__frame"><pose>1.391097e-01 -1.127531e-01 -1.133219e-17 0.000000e+00 -0.000000e+00 0.000000e+00</pose>
<visual name="component_node-6__frame_frame_visual"><pose>-3.330366e-02 4.830212e-02 -1.620470e-17 1.570796e+00 5.551115e-17 2.320911e+00</pose>
<material><ambient>0.36 0.21 0.81 1.00</ambient><diffuse>0.36 0.21 0.81 1.00</diffuse><specular>0.1 0.1 0.1 1.00</specular></material>
<geometry><mesh><uri>model://rg_robot/meshes/ActiveHinge_Frame.dae</uri></mesh></geometry></visual>
<collision name="component_node-6__frame_collision"><pose>-3.330366e-02 4.830212e-02 -1.620470e-17 1.570796e+00 5.551115e-17 2.320911e+00</pose>
<surface><contact><ode><kd>3.333333e+06</kd><kp>9.000000e+04</kp></ode></contact>
<friction><ode><mu>1.000000e+00</mu>
<mu2>1.000000e+00</mu2>
<slip1>1.000000e-02</slip1>
<slip2>1.000000e-02</slip2></ode>
<bullet><friction>1.000000e+00</friction>
<friction2>1.000000e+00</friction2></bullet></friction></surface>
<geometry><box><size>1.800000e-02 3.400000e-02 1.000000e-02</size></box></geometry></collision>
<visual name="component_node-6__root_visual"><pose>-2.658870e-02 4.109576e-02 -1.511113e-17 1.570796e+00 5.551115e-17 2.320911e+00</pose>
<material><ambient>0.36 0.21 0.81 1.00</ambient><diffuse>0.36 0.21 0.81 1.00</diffuse><specular>0.1 0.1 0.1 1.00</specular></material>
<geometry><box><size>1.500000e-03 3.400000e-02 3.400000e-02</size></box></geometry></visual>
<collision name="component_node-6__root_collision"><pose>-2.658870e-02 4.109576e-02 -1.511113e-17 1.570796e+00 5.551115e-17 2.320911e+00</pose>
<surface><contact><ode><kd>3.333333e+06</kd><kp>9.000000e+04</kp></ode></contact>
<friction><ode><mu>1.000000e+00</mu>
<mu2>1.000000e+00</mu2>
<slip1>1.000000e-02</slip1>
<slip2>1.000000e-02</slip2></ode>
<bullet><friction>1.000000e+00</friction>
<friction2>1.000000e+00</friction2></bullet></friction></surface>
<geometry><box><size>1.500000e-03 3.400000e-02 3.400000e-02</size></box></geometry></collision>
<visual name="component_node-7__tail_visual"><pose>-2.556611e-02 3.999834e-02 -1.486725e-17 1.570796e+00 2.220446e-16 2.320911e+00</pose>
<material><ambient>0.36 0.21 0.81 1.00</ambient><diffuse>0.36 0.21 0.81 1.00</diffuse><specular>0.1 0.1 0.1 1.00</specular></material>
<geometry><box><size>1.500000e-03 3.400000e-02 3.400000e-02</size></box></geometry></visual>
<collision name="component_node-7__tail_collision"><pose>-2.556611e-02 3.999834e-02 -1.486725e-17 1.570796e+00 2.220446e-16 2.320911e+00</pose>
<surface><contact><ode><kd>3.333333e+06</kd><kp>9.000000e+04</kp></ode></contact>
<friction><ode><mu>1.000000e+00</mu>
<mu2>1.000000e+00</mu2>
<slip1>1.000000e-02</slip1>
<slip2>1.000000e-02</slip2></ode>
<bullet><friction>1.000000e+00</friction>
<friction2>1.000000e+00</friction2></bullet></friction></surface>
<geometry><box><size>1.500000e-03 3.400000e-02 3.400000e-02</size></box></geometry></collision>
<visual name="component_node-7__connection_visual"><pose>-7.356107e-03 1.171303e-02 -5.530217e-18 1.570796e+00 2.775558e-16 2.142799e+00</pose>
<material><ambient>0.36 0.21 0.81 1.00</ambient><diffuse>0.36 0.21 0.81 1.00</diffuse><specular>0.1 0.1 0.1 1.00</specular></material>
<geometry><box><size>6.578040e-02 2.000000e-02 2.000000e-03</size></box></geometry></visual>
<collision name="component_node-7__connection_collision"><pose>-7.356107e-03 1.171303e-02 -5.530217e-18 1.570796e+00 2.775558e-16 2.142799e+00</pose>
<surface><contact><ode><kd>3.333333e+06</kd><kp>9.000000e+04</kp></ode></contact>
<friction><ode><mu>1.000000e+00</mu>
<mu2>1.000000e+00</mu2>
<slip1>1.000000e-02</slip1>
<slip2>1.000000e-02</slip2></ode>
<bullet><friction>1.000000e+00</friction>
<friction2>1.000000e+00</friction2></bullet></friction></surface>
<geometry><box><size>6.578040e-02 2.000000e-02 2.000000e-03</size></box></geometry></collision>
<visual name="component_node-7__root_visual"><pose>1.085390e-02 -1.657228e-02 3.806815e-18 1.570796e+00 2.775558e-16 2.142799e+00</pose>
<material><ambient>0.36 0.21 0.81 1.00</ambient><diffuse>0.36 0.21 0.81 1.00</diffuse><specular>0.1 0.1 0.1 1.00</specular></material>
<geometry><box><size>1.500000e-03 3.400000e-02 3.400000e-02</size></box></geometry></visual>
<collision name="component_node-7__root_collision"><pose>1.085390e-02 -1.657228e-02 3.806815e-18 1.570796e+00 2.775558e-16 2.142799e+00</pose>
<surface><contact><ode><kd>3.333333e+06</kd><kp>9.000000e+04</kp></ode></contact>
<friction><ode><mu>1.000000e+00</mu>
<mu2>1.000000e+00</mu2>
<slip1>1.000000e-02</slip1>
<slip2>1.000000e-02</slip2></ode>
<bullet><friction>1.000000e+00</friction>
<friction2>1.000000e+00</friction2></bullet></friction></surface>
<geometry><box><size>1.500000e-03 3.400000e-02 3.400000e-02</size></box></geometry></collision>
<collision name="component_node-8__tail_collision"><pose>1.166587e-02 -1.783351e-02 4.472949e-18 1.570796e+00 6.661338e-16 2.142799e+00</pose>
<surface><contact><ode><kd>3.333333e+06</kd><kp>9.000000e+04</kp></ode></contact>
<friction><ode><mu>1.000000e+00</mu>
<mu2>1.000000e+00</mu2>
<slip1>1.000000e-02</slip1>
<slip2>1.000000e-02</slip2></ode>
<bullet><friction>1.000000e+00</friction>
<friction2>1.000000e+00</friction2></bullet></friction></surface>
<geometry><box><size>1.500000e-03 3.400000e-02 3.400000e-02</size></box></geometry></collision>
<visual name="component_node-8__servo_servo_visual"><pose>1.875712e-02 -2.884823e-02 1.247211e-17 1.570796e+00 6.661338e-16 2.142799e+00</pose>
<material><ambient>0.36 0.21 0.81 1.00</ambient><diffuse>0.36 0.21 0.81 1.00</diffuse><specular>0.1 0.1 0.1 1.00</specular></material>
<geometry><mesh><uri>model://rg_robot/meshes/ActiveCardanHinge_Servo_Holder.dae</uri></mesh></geometry></visual>
<collision name="component_node-8__servo_collision"><pose>1.875712e-02 -2.884823e-02 1.247211e-17 1.570796e+00 6.661338e-16 2.142799e+00</pose>
<surface><contact><ode><kd>3.333333e+06</kd><kp>9.000000e+04</kp></ode></contact>
<friction><ode><mu>1.000000e+00</mu>
<mu2>1.000000e+00</mu2>
<slip1>1.000000e-02</slip1>
<slip2>1.000000e-02</slip2></ode>
<bullet><friction>1.000000e+00</friction>
<friction2>1.000000e+00</friction2></bullet></friction></surface>
<geometry><box><size>2.450000e-02 3.400000e-02 1.000000e-02</size></box></geometry></collision>
<inertial><mass>2.751561e-02</mass><inertia><ixx>3.024436e-05</ixx><ixy>1.688522e-05</ixy><ixz>-6.663808e-21</ixz><iyy>1.511235e-05</iyy><iyz>8.775720e-21</iyz><izz>4.022114e-05</izz></inertia></inertial>
<self_collide>True</self_collide></link>
<link name="link_component_node-8__frame"><pose>1.910269e-01 -1.914303e-01 3.354940e-17 0.000000e+00 -0.000000e+00 0.000000e+00</pose>
<visual name="component_node-8__frame_frame_visual"><pose>-2.598763e-02 3.868818e-02 -2.431874e-17 1.570796e+00 6.661338e-16 2.142799e+00</pose>
<material><ambient>0.36 0.21 0.81 1.00</ambient><diffuse>0.36 0.21 0.81 1.00</diffuse><specular>0.1 0.1 0.1 1.00</specular></material>
<geometry><mesh><uri>model://rg_robot/meshes/ActiveHinge_Frame.dae</uri></mesh></geometry></visual>
<collision name="component_node-8__frame_collision"><pose>-2.598763e-02 3.868818e-02 -2.431874e-17 1.570796e+00 6.661338e-16 2.142799e+00</pose>
<surface><contact><ode><kd>3.333333e+06</kd><kp>9.000000e+04</kp></ode></contact>
<friction><ode><mu>1.000000e+00</mu>
<mu2>1.000000e+00</mu2>
<slip1>1.000000e-02</slip1>
<slip2>1.000000e-02</slip2></ode>
<bullet><friction>1.000000e+00</friction>
<friction2>1.000000e+00</friction2></bullet></friction></surface>
<geometry><box><size>1.800000e-02 3.400000e-02 1.000000e-02</size></box></geometry></collision>
<visual name="component_node-8__root_visual"><pose>-2.065566e-02 3.040611e-02 -1.830411e-17 1.570796e+00 6.661338e-16 2.142799e+00</pose>
<material><ambient>0.36 0.21 0.81 1.00</ambient><diffuse>0.36 0.21 0.81 1.00</diffuse><specular>0.1 0.1 0.1 1.00</specular></material>
<geometry><box><size>1.500000e-03 3.400000e-02 3.400000e-02</size></box></geometry></visual>
<collision name="component_node-8__root_collision"><pose>-2.065566e-02 3.040611e-02 -1.830411e-17 1.570796e+00 6.661338e-16 2.142799e+00</pose>
<surface><contact><ode><kd>3.333333e+06</kd><kp>9.000000e+04</kp></ode></contact>
<friction><ode><mu>1.000000e+00</mu>
<mu2>1.000000e+00</mu2>
<slip1>1.000000e-02</slip1>
<slip2>1.000000e-02</slip2></ode>
<bullet><friction>1.000000e+00</friction>
<friction2>1.000000e+00</friction2></bullet></friction></surface>
<geometry><box><size>1.500000e-03 3.400000e-02 3.400000e-02</size></box></geometry></collision>
<visual name="component_node-9__tail_visual"><pose>-1.984368e-02 2.914489e-02 -1.740065e-17 1.570796e+00 5.551115e-16 2.142799e+00</pose>
<material><ambient>0.36 0.21 0.81 1.00</ambient><diffuse>0.36 0.21 0.81 1.00</diffuse><specular>0.1 0.1 0.1 1.00</specular></material>
<geometry><box><size>1.500000e-03 3.400000e-02 3.400000e-02</size></box></geometry></visual>
<collision name="component_node-9__tail_collision"><pose>-1.984368e-02 2.914489e-02 -1.740065e-17 1.570796e+00 5.551115e-16 2.142799e+00</pose>
<surface><contact><ode><kd>3.333333e+06</kd><kp>9.000000e+04</kp></ode></contact>
<friction><ode><mu>1.000000e+00</mu>
<mu2>1.000000e+00</mu2>
<slip1>1.000000e-02</slip1>
<slip2>1.000000e-02</slip2></ode>
<bullet><friction>1.000000e+00</friction>
<friction2>1.000000e+00</friction2></bullet></friction></surface>
<geometry><box><size>1.500000e-03 3.400000e-02 3.400000e-02</size></box></geometry></collision>
<visual name="component_node-9__connection_visual"><pose>-6.341466e-03 9.286827e-03 -4.070427e-18 1.570796e+00 5.551115e-16 2.167929e+00</pose>
<material><ambient>0.36 0.21 0.81 1.00</ambient><diffuse>0.36 0.21 0.81 1.00</diffuse><specular>0.1 0.1 0.1 1.00</specular></material>
<geometry><box><size>4.652718e-02 2.000000e-02 2.000000e-03</size></box></geometry></visual>
<collision name="component_node-9__connection_collision"><pose>-6.341466e-03 9.286827e-03 -4.070427e-18 1.570796e+00 5.551115e-16 2.167929e+00</pose>
<surface><contact><ode><kd>3.333333e+06</kd><kp>9.000000e+04</kp></ode></contact>
<friction><ode><mu>1.000000e+00</mu>
<mu2>1.000000e+00</mu2>
<slip1>1.000000e-02</slip1>
<slip2>1.000000e-02</slip2></ode>
<bullet><friction>1.000000e+00</friction>
<friction2>1.000000e+00</friction2></bullet></friction></surface>
<geometry><box><size>4.652718e-02 2.000000e-02 2.000000e-03</size></box></geometry></collision>
<visual name="component_node-9__root_visual"><pose>7.160751e-03 -1.057123e-02 9.259792e-18 1.570796e+00 5.551115e-16 2.167929e+00</pose>
<material><ambient>0.36 0.21 0.81 1.00</ambient><diffuse>0.36 0.21 0.81 1.00</diffuse><specular>0.1 0.1 0.1 1.00</specular></material>
<geometry><box><size>1.500000e-03 3.400000e-02 3.400000e-02</size></box></geometry></visual>
<collision name="component_node-9__root_collision"><pose>7.160751e-03 -1.057123e-02 9.259792e-18 1.570796e+00 5.551115e-16 2.167929e+00</pose>
<surface><contact><ode><kd>3.333333e+06</kd><kp>9.000000e+04</kp></ode></contact>
<friction><ode><mu>1.000000e+00</mu>
<mu2>1.000000e+00</mu2>
<slip1>1.000000e-02</slip1>
<slip2>1.000000e-02</slip2></ode>
<bullet><friction>1.000000e+00</friction>
<friction2>1.000000e+00</friction2></bullet></friction></surface>
<geometry><box><size>1.500000e-03 3.400000e-02 3.400000e-02</size></box></geometry></collision>
<collision name="component_node-10__tail_collision"><pose>8.004162e-03 -1.181166e-02 9.759392e-18 1.570796e+00 1.665335e-16 2.167929e+00</pose>
<surface><contact><ode><kd>3.333333e+06</kd><kp>9.000000e+04</kp></ode></contact>
<friction><ode><mu>1.000000e+00</mu>
<mu2>1.000000e+00</mu2>
<slip1>1.000000e-02</slip1>
<slip2>1.000000e-02</slip2></ode>
<bullet><friction>1.000000e+00</friction>
<friction2>1.000000e+00</friction2></bullet></friction></surface>
<geometry><box><size>1.500000e-03 3.400000e-02 3.400000e-02</size></box></geometry></collision>
<visual name="component_node-10__servo_servo_visual"><pose>1.536995e-02 -2.264472e-02 1.121378e-17 1.570796e+00 1.665335e-16 2.167929e+00</pose>
<material><ambient>0.36 0.21 0.81 1.00</ambient><diffuse>0.36 0.21 0.81 1.00</diffuse><specular>0.1 0.1 0.1 1.00</specular></material>
<geometry><mesh><uri>model://rg_robot/meshes/ActiveCardanHinge_Servo_Holder.dae</uri></mesh></geometry></visual>
<collision name="component_node-10__servo_collision"><pose>1.536995e-02 -2.264472e-02 1.121378e-17 1.570796e+00 1.665335e-16 2.167929e+00</pose>
<surface><contact><ode><kd>3.333333e+06</kd><kp>9.000000e+04</kp></ode></contact>
<friction><ode><mu>1.000000e+00</mu>
<mu2>1.000000e+00</mu2>
<slip1>1.000000e-02</slip1>
<slip2>1.000000e-02</slip2></ode>
<bullet><friction>1.000000e+00</friction>
<friction2>1.000000e+00</friction2></bullet></friction></surface>
<geometry><box><size>2.450000e-02 3.400000e-02 1.000000e-02</size></box></geometry></collision>
<inertial><mass>2.713054e-02</mass><inertia><ixx>1.839975e-05</ixx><ixy>9.660807e-06</ixy><ixz>-6.662656e-21</ixz><iyy>1.074527e-05</iyy><iyz>7.296796e-21</iyz><izz>2.403511e-05</izz></inertia></inertial>
<self_collide>True</self_collide></link>
<link name="link_component_node-10__frame"><pose>2.303814e-01 -2.657327e-01 5.825061e-17 0.000000e+00 -0.000000e+00 0.000000e+00</pose>
<visual name="component_node-10__frame_frame_visual"><pose>-1.653441e-02 4.070052e-02 -1.201638e-17 1.570796e+00 1.665335e-16 2.167929e+00</pose>
<material><ambient>0.36 0.21 0.81 1.00</ambient><diffuse>0.36 0.21 0.81 1.00</diffuse><specular>0.1 0.1 0.1 1.00</specular></material>
<geometry><mesh><uri>model://rg_robot/meshes/ActiveHinge_Frame.dae</uri></mesh></geometry></visual>
<collision name="component_node-10__frame_collision"><pose>-1.653441e-02 4.070052e-02 -1.201638e-17 1.570796e+00 1.665335e-16 2.167929e+00</pose>
<surface><contact><ode><kd>3.333333e+06</kd><kp>9.000000e+04</kp></ode></contact>
<friction><ode><mu>1.000000e+00</mu>
<mu2>1.000000e+00</mu2>
<slip1>1.000000e-02</slip1>
<slip2>1.000000e-02</slip2></ode>
<bullet><friction>1.000000e+00</friction>
<friction2>1.000000e+00</friction2></bullet></friction></surface>
<geometry><box><size>1.800000e-02 3.400000e-02 1.000000e-02</size></box></geometry></collision>
<visual name="component_node-10__root_visual"><pose>-1.099601e-02 3.255506e-02 -1.092281e-17 1.570796e+00 1.665335e-16 2.167929e+00</pose>
<material><ambient>0.36 0.21 0.81 1.00</ambient><diffuse>0.36 0.21 0.81 1.00</diffuse><specular>0.1 0.1 0.1 1.00</specular></material>
<geometry><box><size>1.500000e-03 3.400000e-02 3.400000e-02</size></box></geometry></visual>
<collision name="component_node-10__root_collision"><pose>-1.099601e-02 3.255506e-02 -1.092281e-17 1.570796e+00 1.665335e-16 2.167929e+00</pose>
<surface><contact><ode><kd>3.333333e+06</kd><kp>9.000000e+04</kp></ode></contact>
<friction><ode><mu>1.000000e+00</mu>
<mu2>1.000000e+00</mu2>
<slip1>1.000000e-02</slip1>
<slip2>1.000000e-02</slip2></ode>
<bullet><friction>1.000000e+00</friction>
<friction2>1.000000e+00</friction2></bullet></friction></surface>
<geometry><box><size>1.500000e-03 3.400000e-02 3.400000e-02</size></box></geometry></collision>
<visual name="component_node-11__tail_visual"><pose>-1.015260e-02 3.131463e-02 -1.093985e-17 1.570796e+00 -5.551115e-17 2.167929e+00</pose>
<material><ambient>0.36 0.21 0.81 1.00</ambient><diffuse>0.36 0.21 0.81 1.00</diffuse><specular>0.1 0.1 0.1 1.00</specular></material>
<geometry><box><size>1.500000e-03 3.400000e-02 3.400000e-02</size></box></geometry></visual>
<collision name="component_node-11__tail_collision"><pose>-1.015260e-02 3.131463e-02 -1.093985e-17 1.570796e+00 -5.551115e-17 2.167929e+00</pose>
<surface><contact><ode><kd>3.333333e+06</kd><kp>9.000000e+04</kp></ode></contact>
<friction><ode><mu>1.000000e+00</mu>
<mu2>1.000000e+00</mu2>
<slip1>1.000000e-02</slip1>
<slip2>1.000000e-02</slip2></ode>
<bullet><friction>1.000000e+00</friction>
<friction2>1.000000e+00</friction2></bullet></friction></surface>
<geometry><box><size>1.500000e-03 3.400000e-02 3.400000e-02</size></box></geometry></collision>
<visual name="component_node-11__connection_visual"><pose>-3.166960e-03 1.029853e-02 -3.563519e-18 1.570796e+00 3.330669e-16 1.891702e+00</pose>
<material><ambient>0.36 0.21 0.81 1.00</ambient><diffuse>0.36 0.21 0.81 1.00</diffuse><specular>0.1 0.1 0.1 1.00</specular></material>
<geometry><box><size>4.279337e-02 2.000000e-02 2.000000e-03</size></box></geometry></visual>
<collision name="component_node-11__connection_collision"><pose>-3.166960e-03 1.029853e-02 -3.563519e-18 1.570796e+00 3.330669e-16 1.891702e+00</pose>
<surface><contact><ode><kd>3.333333e+06</kd><kp>9.000000e+04</kp></ode></contact>
<friction><ode><mu>1.000000e+00</mu>
<mu2>1.000000e+00</mu2>
<slip1>1.000000e-02</slip1>
<slip2>1.000000e-02</slip2></ode>
<bullet><friction>1.000000e+00</friction>
<friction2>1.000000e+00</friction2></bullet></friction></surface>
<geometry><box><size>4.279337e-02 2.000000e-02 2.000000e-03</size></box></geometry></collision>
<visual name="component_node-11__root_visual"><pose>3.818678e-03 -1.071758e-02 3.812809e-18 1.570796e+00 3.330669e-16 1.891702e+00</pose>
<material><ambient>0.36 0.21 0.81 1.00</ambient><diffuse>0.36 0.21 0.81 1.00</diffuse><specular>0.1 0.1 0.1 1.00</specular></material>
<geometry><box><size>1.500000e-03 3.400000e-02 3.400000e-02</size></box></geometry></visual>
<collision name="component_node-11__root_collision"><pose>3.818678e-03 -1.071758e-02 3.812809e-18 1.570796e+00 3.330669e-16 1.891702e+00</pose>
<surface><contact><ode><kd>3.333333e+06</kd><kp>9.000000e+04</kp></ode></contact>
<friction><ode><mu>1.000000e+00</mu>
<mu2>1.000000e+00</mu2>
<slip1>1.000000e-02</slip1>
<slip2>1.000000e-02</slip2></ode>
<bullet><friction>1.000000e+00</friction>
<friction2>1.000000e+00</friction2></bullet></friction></surface>
<geometry><box><size>1.500000e-03 3.400000e-02 3.400000e-02</size></box></geometry></collision>
<collision name="component_node-12__tail_collision"><pose>4.291816e-03 -1.214100e-02 4.270776e-18 1.570796e+00 1.110223e-16 1.891702e+00</pose>
<surface><contact><ode><kd>3.333333e+06</kd><kp>9.000000e+04</kp></ode></contact>
<friction><ode><mu>1.000000e+00</mu>
<mu2>1.000000e+00</mu2>
<slip1>1.000000e-02</slip1>
<slip2>1.000000e-02</slip2></ode>
<bullet><friction>1.000000e+00</friction>
<friction2>1.000000e+00</friction2></bullet></friction></surface>
<geometry><box><size>1.500000e-03 3.400000e-02 3.400000e-02</size></box></geometry></collision>
<visual name="component_node-12__servo_servo_visual"><pose>8.423895e-03 -2.457225e-02 7.906756e-18 1.570796e+00 1.110223e-16 1.891702e+00</pose>
<material><ambient>0.36 0.21 0.81 1.00</ambient><diffuse>0.36 0.21 0.81 1.00</diffuse><specular>0.1 0.1 0.1 1.00</specular></material>
<geometry><mesh><uri>model://rg_robot/meshes/ActiveCardanHinge_Servo_Holder.dae</uri></mesh></geometry></visual>
<collision name="component_node-12__servo_collision"><pose>8.423895e-03 -2.457225e-02 7.906756e-18 1.570796e+00 1.110223e-16 1.891702e+00</pose>
<surface><contact><ode><kd>3.333333e+06</kd><kp>9.000000e+04</kp></ode></contact>
<friction><ode><mu>1.000000e+00</mu>
<mu2>1.000000e+00</mu2>
<slip1>1.000000e-02</slip1>
<slip2>1.000000e-02</slip2></ode>
<bullet><friction>1.000000e+00</friction>
<friction2>1.000000e+00</friction2></bullet></friction></surface>
<geometry><box><size>2.450000e-02 3.400000e-02 1.000000e-02</size></box></geometry></collision>
<inertial><mass>2.705587e-02</mass><inertia><ixx>2.048988e-05</ixx><ixy>5.501698e-06</ixy><ixz>-3.421935e-21</ixz><iyy>5.985044e-06</iyy><iyz>4.917476e-21</iyz><izz>2.137000e-05</izz></inertia></inertial>
<self_collide>True</self_collide></link>
<link name="link_component_node-12__frame"><pose>2.270640e-01 -3.482924e-01 1.353449e-16 0.000000e+00 -0.000000e+00 0.000000e+00</pose>
<visual name="component_node-12__frame_frame_visual"><pose>1.592072e-02 4.541391e-02 -6.550995e-17 1.570796e+00 1.110223e-16 1.891702e+00</pose>
<material><ambient>0.36 0.21 0.81 1.00</ambient><diffuse>0.36 0.21 0.81 1.00</diffuse><specular>0.1 0.1 0.1 1.00</specular></material>
<geometry><mesh><uri>model://rg_robot/meshes/ActiveHinge_Frame.dae</uri></mesh></geometry></visual>
<collision name="component_node-12__frame_collision"><pose>1.592072e-02 4.541391e-02 -6.550995e-17 1.570796e+00 1.110223e-16 1.891702e+00</pose>
<surface><contact><ode><kd>3.333333e+06</kd><kp>9.000000e+04</kp></ode></contact>
<friction><ode><mu>1.000000e+00</mu>
<mu2>1.000000e+00</mu2>
<slip1>1.000000e-02</slip1>
<slip2>1.000000e-02</slip2></ode>
<bullet><friction>1.000000e+00</friction>
<friction2>1.000000e+00</friction2></bullet></friction></surface>
<geometry><box><size>1.800000e-02 3.400000e-02 1.000000e-02</size></box></geometry></collision>
<visual name="component_node-12__root_visual"><pose>1.902767e-02 3.606675e-02 -6.277602e-17 1.570796e+00 1.110223e-16 1.891702e+00</pose>
<material><ambient>0.36 0.21 0.81 1.00</ambient><diffuse>0.36 0.21 0.81 1.00</diffuse><specular>0.1 0.1 0.1 1.00</specular></material>
<geometry><box><size>1.500000e-03 3.400000e-02 3.400000e-02</size></box></geometry></visual>
<collision name="component_node-12__root_collision"><pose>1.902767e-02 3.606675e-02 -6.277602e-17 1.570796e+00 1.110223e-16 1.891702e+00</pose>
<surface><contact><ode><kd>3.333333e+06</kd><kp>9.000000e+04</kp></ode></contact>
<friction><ode><mu>1.000000e+00</mu>
<mu2>1.000000e+00</mu2>
<slip1>1.000000e-02</slip1>
<slip2>1.000000e-02</slip2></ode>
<bullet><friction>1.000000e+00</friction>
<friction2>1.000000e+00</friction2></bullet></friction></surface>
<geometry><box><size>1.500000e-03 3.400000e-02 3.400000e-02</size></box></geometry></collision>
<visual name="component_node-13__tail_visual"><pose>1.950081e-02 3.464333e-02 -6.252946e-17 1.570796e+00 1.110223e-16 1.891702e+00</pose>
<material><ambient>0.36 0.21 0.81 1.00</ambient><diffuse>0.36 0.21 0.81 1.00</diffuse><specular>0.1 0.1 0.1 1.00</specular></material>
<geometry><box><size>1.500000e-03 3.400000e-02 3.400000e-02</size></box></geometry></visual>
<collision name="component_node-13__tail_collision"><pose>1.950081e-02 3.464333e-02 -6.252946e-17 1.570796e+00 1.110223e-16 1.891702e+00</pose>
<surface><contact><ode><kd>3.333333e+06</kd><kp>9.000000e+04</kp></ode></contact>
<friction><ode><mu>1.000000e+00</mu>
<mu2>1.000000e+00</mu2>
<slip1>1.000000e-02</slip1>
<slip2>1.000000e-02</slip2></ode>
<bullet><friction>1.000000e+00</friction>
<friction2>1.000000e+00</friction2></bullet></friction></surface>
<geometry><box><size>1.500000e-03 3.400000e-02 3.400000e-02</size></box></geometry></collision>
<visual name="component_node-13__connection_visual"><pose>6.482689e-03 1.061220e-02 -2.004904e-17 1.570796e+00 1.498801e-15 1.074333e+00</pose>
<material><ambient>0.36 0.21 0.81 1.00</ambient><diffuse>0.36 0.21 0.81 1.00</diffuse><specular>0.1 0.1 0.1 1.00</specular></material>
<geometry><box><size>5.316137e-02 2.000000e-02 2.000000e-03</size></box></geometry></visual>
<collision name="component_node-13__connection_collision"><pose>6.482689e-03 1.061220e-02 -2.004904e-17 1.570796e+00 1.498801e-15 1.074333e+00</pose>
<surface><contact><ode><kd>3.333333e+06</kd><kp>9.000000e+04</kp></ode></contact>
<friction><ode><mu>1.000000e+00</mu>
<mu2>1.000000e+00</mu2>
<slip1>1.000000e-02</slip1>
<slip2>1.000000e-02</slip2></ode>
<bullet><friction>1.000000e+00</friction>
<friction2>1.000000e+00</friction2></bullet></friction></surface>
<geometry><box><size>5.316137e-02 2.000000e-02 2.000000e-03</size></box></geometry></collision>
<visual name="component_node-13__root_visual"><pose>-6.535429e-03 -1.341892e-02 2.243137e-17 1.570796e+00 1.498801e-15 1.074333e+00</pose>
<material><ambient>0.36 0.21 0.81 1.00</ambient><diffuse>0.36 0.21 0.81 1.00</diffuse><specular>0.1 0.1 0.1 1.00</specular></material>
<geometry><box><size>1.500000e-03 3.400000e-02 3.400000e-02</size></box></geometry></visual>
<collision name="component_node-13__root_collision"><pose>-6.535429e-03 -1.341892e-02 2.243137e-17 1.570796e+00 1.498801e-15 1.074333e+00</pose>
<surface><contact><ode><kd>3.333333e+06</kd><kp>9.000000e+04</kp></ode></contact>
<friction><ode><mu>1.000000e+00</mu>
<mu2>1.000000e+00</mu2>
<slip1>1.000000e-02</slip1>
<slip2>1.000000e-02</slip2></ode>
<bullet><friction>1.000000e+00</friction>
<friction2>1.000000e+00</friction2></bullet></friction></surface>
<geometry><box><size>1.500000e-03 3.400000e-02 3.400000e-02</size></box></geometry></collision>
<collision name="component_node-14__tail_collision"><pose>-7.249907e-03 -1.473783e-02 2.476284e-17 1.570796e+00 1.554312e-15 1.074333e+00</pose>
<surface><contact><ode><kd>3.333333e+06</kd><kp>9.000000e+04</kp></ode></contact>
<friction><ode><mu>1.000000e+00</mu>
<mu2>1.000000e+00</mu2>
<slip1>1.000000e-02</slip1>
<slip2>1.000000e-02</slip2></ode>
<bullet><friction>1.000000e+00</friction>
<friction2>1.000000e+00</friction2></bullet></friction></surface>
<geometry><box><size>1.500000e-03 3.400000e-02 3.400000e-02</size></box></geometry></collision>
<visual name="component_node-14__servo_servo_visual"><pose>-1.348968e-02 -2.625630e-02 4.512433e-17 1.570796e+00 1.554312e-15 1.074333e+00</pose>
<material><ambient>0.36 0.21 0.81 1.00</ambient><diffuse>0.36 0.21 0.81 1.00</diffuse><specular>0.1 0.1 0.1 1.00</specular></material>
<geometry><mesh><uri>model://rg_robot/meshes/ActiveCardanHinge_Servo_Holder.dae</uri></mesh></geometry></visual>
<collision name="component_node-14__servo_collision"><pose>-1.348968e-02 -2.625630e-02 4.512433e-17 1.570796e+00 1.554312e-15 1.074333e+00</pose>
<surface><contact><ode><kd>3.333333e+06</kd><kp>9.000000e+04</kp></ode></contact>
<friction><ode><mu>1.000000e+00</mu>
<mu2>1.000000e+00</mu2>
<slip1>1.000000e-02</slip1>
<slip2>1.000000e-02</slip2></ode>
<bullet><friction>1.000000e+00</friction>
<friction2>1.000000e+00</friction2></bullet></friction></surface>
<geometry><box><size>2.450000e-02 3.400000e-02 1.000000e-02</size></box></geometry></collision>
<inertial><mass>2.726323e-02</mass><inertia><ixx>2.420783e-05</ixx><ixy>-1.060679e-05</ixy><ixz>1.576542e-20</ixz><iyy>9.390984e-06</iyy><iyz>3.455655e-20</iyz><izz>2.848007e-05</izz></inertia></inertial>
<self_collide>True</self_collide></link>
<link name="link_component_node-14__frame"><pose>2.028023e-01 -3.993164e-01 2.189877e-16 0.000000e+00 -0.000000e+00 0.000000e+00</pose>
<visual name="component_node-14__frame_frame_visual"><pose>4.460778e-03 1.311729e-02 -1.792377e-17 1.570796e+00 1.554312e-15 1.074333e+00</pose>
<material><ambient>0.36 0.21 0.81 1.00</ambient><diffuse>0.36 0.21 0.81 1.00</diffuse><specular>0.1 0.1 0.1 1.00</specular></material>
<geometry><mesh><uri>model://rg_robot/meshes/ActiveHinge_Frame.dae</uri></mesh></geometry></visual>
<collision name="component_node-14__frame_collision"><pose>4.460778e-03 1.311729e-02 -1.792377e-17 1.570796e+00 1.554312e-15 1.074333e+00</pose>
<surface><contact><ode><kd>3.333333e+06</kd><kp>9.000000e+04</kp></ode></contact>
<friction><ode><mu>1.000000e+00</mu>
<mu2>1.000000e+00</mu2>
<slip1>1.000000e-02</slip1>
<slip2>1.000000e-02</slip2></ode>
<bullet><friction>1.000000e+00</friction>
<friction2>1.000000e+00</friction2></bullet></friction></surface>
<geometry><box><size>1.800000e-02 3.400000e-02 1.000000e-02</size></box></geometry></collision>
<visual name="component_node-14__root_visual"><pose>-2.309619e-04 4.456457e-03 -2.613798e-18 1.570796e+00 1.554312e-15 1.074333e+00</pose>
<material><ambient>0.36 0.21 0.81 1.00</ambient><diffuse>0.36 0.21 0.81 1.00</diffuse><specular>0.1 0.1 0.1 1.00</specular></material>
<geometry><box><size>1.500000e-03 3.400000e-02 3.400000e-02</size></box></geometry></visual>
<collision name="component_node-14__root_collision"><pose>-2.309619e-04 4.456457e-03 -2.613798e-18 1.570796e+00 1.554312e-15 1.074333e+00</pose>
<surface><contact><ode><kd>3.333333e+06</kd><kp>9.000000e+04</kp></ode></contact>
<friction><ode><mu>1.000000e+00</mu>
<mu2>1.000000e+00</mu2>
<slip1>1.000000e-02</slip1>
<slip2>1.000000e-02</slip2></ode>
<bullet><friction>1.000000e+00</friction>
<friction2>1.000000e+00</friction2></bullet></friction></surface>
<geometry><box><size>1.500000e-03 3.400000e-02 3.400000e-02</size></box></geometry></collision>
<visual name="component_node-15__tail_visual"><pose>-9.454401e-04 3.137548e-03 -1.269907e-19 1.570796e+00 1.776357e-15 1.074333e+00</pose>
<material><ambient>0.01 0.29 0.62 1.00</ambient><diffuse>0.01 0.29 0.62 1.00</diffuse><specular>0.1 0.1 0.1 1.00</specular></material>
<geometry><box><size>1.500000e-03 3.400000e-02 3.400000e-02</size></box></geometry></visual>
<collision name="component_node-15__tail_collision"><pose>-9.454401e-04 3.137548e-03 -1.269907e-19 1.570796e+00 1.776357e-15 1.074333e+00</pose>
<surface><contact><ode><kd>3.333333e+06</kd><kp>9.000000e+04</kp></ode></contact>
<friction><ode><mu>1.000000e+00</mu>
<mu2>1.000000e+00</mu2>
<slip1>1.000000e-02</slip1>
<slip2>1.000000e-02</slip2></ode>
<bullet><friction>1.000000e+00</friction>
<friction2>1.000000e+00</friction2></bullet></friction></surface>
<geometry><box><size>1.500000e-03 3.400000e-02 3.400000e-02</size></box></geometry></collision>
<visual name="component_node-15__connection_visual"><pose>-1.347465e-03 -1.692750e-02 1.435576e-17 1.570796e+00 7.771561e-16 1.550763e+00</pose>
<material><ambient>0.01 0.29 0.62 1.00</ambient><diffuse>0.01 0.29 0.62 1.00</diffuse><specular>0.1 0.1 0.1 1.00</specular></material>
<geometry><box><size>3.863815e-02 2.000000e-02 2.000000e-03</size></box></geometry></visual>
<collision name="component_node-15__connection_collision"><pose>-1.347465e-03 -1.692750e-02 1.435576e-17 1.570796e+00 7.771561e-16 1.550763e+00</pose>
<surface><contact><ode><kd>3.333333e+06</kd><kp>9.000000e+04</kp></ode></contact>
<friction><ode><mu>1.000000e+00</mu>
<mu2>1.000000e+00</mu2>
<slip1>1.000000e-02</slip1>
<slip2>1.000000e-02</slip2></ode>
<bullet><friction>1.000000e+00</friction>
<friction2>1.000000e+00</friction2></bullet></friction></surface>
<geometry><box><size>3.863815e-02 2.000000e-02 2.000000e-03</size></box></geometry></collision>
<visual name="component_node-15__root_visual"><pose>-1.749489e-03 -3.699255e-02 2.883850e-17 1.570796e+00 7.771561e-16 1.550763e+00</pose>
<material><ambient>0.01 0.29 0.62 1.00</ambient><diffuse>0.01 0.29 0.62 1.00</diffuse><specular>0.1 0.1 0.1 1.00</specular></material>
<geometry><box><size>1.500000e-03 3.400000e-02 3.400000e-02</size></box></geometry></visual>
<collision name="component_node-15__root_collision"><pose>-1.749489e-03 -3.699255e-02 2.883850e-17 1.570796e+00 7.771561e-16 1.550763e+00</pose>
<surface><contact><ode><kd>3.333333e+06</kd><kp>9.000000e+04</kp></ode></contact>
<friction><ode><mu>1.000000e+00</mu>
<mu2>1.000000e+00</mu2>
<slip1>1.000000e-02</slip1>
<slip2>1.000000e-02</slip2></ode>
<bullet><friction>1.000000e+00</friction>
<friction2>1.000000e+00</friction2></bullet></friction></surface>
<geometry><box><size>1.500000e-03 3.400000e-02 3.400000e-02</size></box></geometry></collision>
<inertial><mass>1.097276e-02</mass><inertia><ixx>3.253228e-06</ixx><ixy>1.703728e-07</ixy><ixz>-6.687269e-22</ixz><iyy>1.745799e-06</iyy><iyz>4.839971e-22</iyz><izz>2.982310e-06</izz></inertia></inertial>
<self_collide>True</self_collide></link>
<joint type="revolute" name="joint_link_component_node-12__frame_link_component_node-14__frame"><pose>6.842372e-03 1.751366e-02 -2.569533e-17 1.570796e+00 1.554312e-15 1.074333e+00</pose>
<parent>link_component_node-12__frame</parent>
<child>link_component_node-14__frame</child>
<axis><xyz>0.000000e+00 1.000000e+00 0.000000e+00</xyz>
<use_parent_model_frame>0</use_parent_model_frame>
<limit><lower>-7.853982e-01</lower>
<upper>7.853982e-01</upper>
<effort>1.765800e-01</effort>
<velocity>5.235988e+00</velocity></limit></axis></joint>
<joint type="revolute" name="joint_link_component_node-10__frame_link_component_node-12__frame"><pose>1.434359e-02 5.015866e-02 -6.689773e-17 1.570796e+00 2.775558e-16 1.891702e+00</pose>
<parent>link_component_node-10__frame</parent>
<child>link_component_node-12__frame</child>
<axis><xyz>0.000000e+00 1.000000e+00 0.000000e+00</xyz>
<use_parent_model_frame>0</use_parent_model_frame>
<limit><lower>-7.853982e-01</lower>
<upper>7.853982e-01</upper>
<effort>1.765800e-01</effort>
<velocity>5.235988e+00</velocity></limit></axis></joint>
<joint type="revolute" name="joint_link_component_node-8__frame_link_component_node-10__frame"><pose>-1.934578e-02 4.483528e-02 -1.257149e-17 1.570796e+00 1.110223e-16 2.167929e+00</pose>
<parent>link_component_node-8__frame</parent>
<child>link_component_node-10__frame</child>
<axis><xyz>0.000000e+00 1.000000e+00 0.000000e+00</xyz>
<use_parent_model_frame>0</use_parent_model_frame>
<limit><lower>-7.853982e-01</lower>
<upper>7.853982e-01</upper>
<effort>1.765800e-01</effort>
<velocity>5.235988e+00</velocity></limit></axis></joint>
<joint type="revolute" name="joint_link_component_node-6__frame_link_component_node-8__frame"><pose>-2.869421e-02 4.289227e-02 -2.737185e-17 1.570796e+00 6.106227e-16 2.142799e+00</pose>
<parent>link_component_node-6__frame</parent>
<child>link_component_node-8__frame</child>
<axis><xyz>0.000000e+00 1.000000e+00 0.000000e+00</xyz>
<use_parent_model_frame>0</use_parent_model_frame>
<limit><lower>-7.853982e-01</lower>
<upper>7.853982e-01</upper>
<effort>1.765800e-01</effort>
<velocity>5.235988e+00</velocity></limit></axis></joint>
<joint type="revolute" name="joint_link_component_node-0__box_link_component_node-6__frame"><pose>-3.671228e-02 5.196018e-02 -1.675981e-17 1.570796e+00 1.110223e-16 2.320911e+00</pose>
<parent>link_component_node-0__box</parent>
<child>link_component_node-6__frame</child>
<axis><xyz>0.000000e+00 1.000000e+00 0.000000e+00</xyz>
<use_parent_model_frame>0</use_parent_model_frame>
<limit><lower>-7.853982e-01</lower>
<upper>7.853982e-01</upper>
<effort>1.765800e-01</effort>
<velocity>5.235988e+00</velocity></limit></axis></joint>
<plugin name="robot_controller" filename="libtolrobotcontrol.so"><rv:robot_config xmlns:rv="https://github.com/ElteHupkes/revolve"><rv:update_rate>8.000000e+00</rv:update_rate>
<rv:brain><rv:neuron layer="input" type="Input" id="node-0-in-0" part_id="node-0" />
<rv:neuron layer="input" type="Input" id="node-0-in-1" part_id="node-0" />
<rv:neuron layer="input" type="Input" id="node-0-in-2" part_id="node-0" />
<rv:neuron layer="input" type="Input" id="node-0-in-3" part_id="node-0" />
<rv:neuron layer="input" type="Input" id="node-0-in-4" part_id="node-0" />
<rv:neuron layer="input" type="Input" id="node-0-in-5" part_id="node-0" />
<rv:neuron layer="output" type="Simple" id="node-1-out-0" part_id="node-1"><rv:bias>-1.416436e-01</rv:bias>
<rv:gain>4.219198e-01</rv:gain></rv:neuron>
<rv:neuron layer="hidden" type="Simple" id="node-1-hidden-0" part_id="node-1"><rv:bias>-2.004195e-01</rv:bias>
<rv:gain>4.853484e-01</rv:gain></rv:neuron>
<rv:neuron layer="output" type="Oscillator" id="node-3-out-0" part_id="node-3"><rv:period>4.223972e+00</rv:period>
<rv:amplitude>1.256676e+00</rv:amplitude>
<rv:phase_offset>2.208825e+00</rv:phase_offset></rv:neuron>
<rv:neuron layer="output" type="Simple" id="node-4-out-0" part_id="node-4"><rv:bias>4.981112e-01</rv:bias>
<rv:gain>2.808814e-01</rv:gain></rv:neuron>
<rv:neuron layer="hidden" type="Simple" id="node-4-hidden-0" part_id="node-4"><rv:bias>-9.673670e-02</rv:bias>
<rv:gain>6.073744e-01</rv:gain></rv:neuron>
<rv:neuron layer="output" type="Oscillator" id="node-6-out-0" part_id="node-6"><rv:period>4.267901e+00</rv:period>
<rv:amplitude>1.043041e+00</rv:amplitude>
<rv:phase_offset>8.882571e-01</rv:phase_offset></rv:neuron>
<rv:neuron layer="output" type="Oscillator" id="node-8-out-0" part_id="node-8"><rv:period>5.085361e+00</rv:period>
<rv:amplitude>1.041085e+00</rv:amplitude>
<rv:phase_offset>1.610078e+00</rv:phase_offset></rv:neuron>
<rv:neuron layer="output" type="Oscillator" id="node-10-out-0" part_id="node-10"><rv:period>4.150400e+00</rv:period>
<rv:amplitude>1.129576e+00</rv:amplitude>
<rv:phase_offset>2.165674e+00</rv:phase_offset></rv:neuron>
<rv:neuron layer="output" type="Oscillator" id="node-12-out-0" part_id="node-12"><rv:period>5.819044e+00</rv:period>
<rv:amplitude>1.378721e+00</rv:amplitude>
<rv:phase_offset>9.927352e-01</rv:phase_offset></rv:neuron>
<rv:neuron layer="output" type="Sigmoid" id="node-14-out-0" part_id="node-14"><rv:bias>1.188196e-01</rv:bias>
<rv:gain>2.476860e-01</rv:gain></rv:neuron>
<rv:neuron layer="input" type="Input" id="node-16-in-0" part_id="node-16" />
<rv:neuron layer="input" type="Input" id="node-16-in-1" part_id="node-16" />
<rv:neural_connection src="node-0-in-3" dst="node-6-out-0" weight="4.509387e-02" />
<rv:neural_connection src="node-0-in-4" dst="node-3-out-0" weight="4.808134e-01" />
<rv:neural_connection src="node-0-in-0" dst="node-6-out-0" weight="2.164981e-01" />
<rv:neural_connection src="node-0-in-2" dst="node-6-out-0" weight="7.001067e-02" />
<rv:neural_connection src="node-0-in-1" dst="node-10-out-0" weight="7.420402e-01" />
<rv:neural_connection src="node-6-out-0" dst="node-12-out-0" weight="8.431298e-01" />
<rv:neural_connection src="node-16-in-0" dst="node-6-out-0" weight="3.910644e-01" />
<rv:neural_connection src="node-16-in-1" dst="node-3-out-0" weight="3.347246e-01" /></rv:brain>
<rv:sensor link="link_component_node-0__box" sensor="node-0-imu_sensor" type="imu" id="node-0__node-0-imu_sensor" part_id="node-0" />
<rv:sensor link="link_component_node-0__box" sensor="node-16-left_sensor" type="touch" id="node-16__node-16-left_sensor" part_id="node-16" />
<rv:sensor link="link_component_node-0__box" sensor="node-16-right_sensor" type="touch" id="node-16__node-16-right_sensor" part_id="node-16" />
<rv:motor joint="joint_link_component_node-0__box_link_component_node-1__frame" type="position" id="node-1__rotate" part_id="node-1"><rv:pid><rv:p>9.000000e-01</rv:p>
<rv:i>0.000000e+00</rv:i>
<rv:d>0.000000e+00</rv:d>
<rv:i_max>0.000000e+00</rv:i_max>
<rv:i_min>0.000000e+00</rv:i_min></rv:pid></rv:motor>
<rv:motor joint="joint_link_component_node-2__conn_b_link_component_node-3__frame" type="position" id="node-3__rotate" part_id="node-3"><rv:pid><rv:p>9.000000e-01</rv:p>
<rv:i>0.000000e+00</rv:i>
<rv:d>0.000000e+00</rv:d>
<rv:i_max>0.000000e+00</rv:i_max>
<rv:i_min>0.000000e+00</rv:i_min></rv:pid></rv:motor>
<rv:motor joint="joint_link_component_node-3__frame_link_component_node-4__frame" type="position" id="node-4__rotate" part_id="node-4"><rv:pid><rv:p>9.000000e-01</rv:p>
<rv:i>0.000000e+00</rv:i>
<rv:d>0.000000e+00</rv:d>
<rv:i_max>0.000000e+00</rv:i_max>
<rv:i_min>0.000000e+00</rv:i_min></rv:pid></rv:motor>
<rv:motor joint="joint_link_component_node-0__box_link_component_node-6__frame" type="position" id="node-6__rotate" part_id="node-6"><rv:pid><rv:p>9.000000e-01</rv:p>
<rv:i>0.000000e+00</rv:i>
<rv:d>0.000000e+00</rv:d>
<rv:i_max>0.000000e+00</rv:i_max>
<rv:i_min>0.000000e+00</rv:i_min></rv:pid></rv:motor>
<rv:motor joint="joint_link_component_node-6__frame_link_component_node-8__frame" type="position" id="node-8__rotate" part_id="node-8"><rv:pid><rv:p>9.000000e-01</rv:p>
<rv:i>0.000000e+00</rv:i>
<rv:d>0.000000e+00</rv:d>
<rv:i_max>0.000000e+00</rv:i_max>
<rv:i_min>0.000000e+00</rv:i_min></rv:pid></rv:motor>
<rv:motor joint="joint_link_component_node-8__frame_link_component_node-10__frame" type="position" id="node-10__rotate" part_id="node-10"><rv:pid><rv:p>9.000000e-01</rv:p>
<rv:i>0.000000e+00</rv:i>
<rv:d>0.000000e+00</rv:d>
<rv:i_max>0.000000e+00</rv:i_max>
<rv:i_min>0.000000e+00</rv:i_min></rv:pid></rv:motor>
<rv:motor joint="joint_link_component_node-10__frame_link_component_node-12__frame" type="position" id="node-12__rotate" part_id="node-12"><rv:pid><rv:p>9.000000e-01</rv:p>
<rv:i>0.000000e+00</rv:i>
<rv:d>0.000000e+00</rv:d>
<rv:i_max>0.000000e+00</rv:i_max>
<rv:i_min>0.000000e+00</rv:i_min></rv:pid></rv:motor>
<rv:motor joint="joint_link_component_node-12__frame_link_component_node-14__frame" type="position" id="node-14__rotate" part_id="node-14"><rv:pid><rv:p>9.000000e-01</rv:p>
<rv:i>0.000000e+00</rv:i>
<rv:d>0.000000e+00</rv:d>
<rv:i_max>0.000000e+00</rv:i_max>
<rv:i_min>0.000000e+00</rv:i_min></rv:pid></rv:motor>
<rv:battery><rv:level>0.000000e+00</rv:level></rv:battery></rv:robot_config></plugin>
<static>0</static></model></sdf>