<?xml version="1.0"?>
<sdf version="1.5"><model name="gen__12200"><pose>0.000000e+00 0.000000e+00 2.250000e-02 0.000000e+00 -0.000000e+00 0.000000e+00</pose>
<link name="link_component_node-0__box"><pose>2.122954e-03 -2.122954e-03 6.593184e-21 0.000000e+00 -0.000000e+00 0.000000e+00</pose>
<visual name="component_node-0__box_visual"><pose>-2.122954e-03 2.122954e-03 -6.593184e-21 0.000000e+00 -0.000000e+00 0.000000e+00</pose>
<material><ambient>0.55 0.16 0.65 1.00</ambient><diffuse>0.55 0.16 0.65 1.00</diffuse><specular>0.1 0.1 0.1 1.00</specular></material>
<geometry><mesh><uri>model://rg_robot/meshes/CoreComponent.dae</uri></mesh></geometry></visual>
<collision name="component_node-0__box_collision"><pose>-2.122954e-03 2.122954e-03 -6.593184e-21 0.000000e+00 -0.000000e+00 0.000000e+00</pose>
<surface><contact><ode><kd>3.333333e+06</kd><kp>9.000000e+04</kp></ode></contact>
<friction><ode><mu>1.000000e+00</mu>
<mu2>1.000000e+00</mu2>
<slip1>1.000000e-02</slip1>
<slip2>1.000000e-02</slip2></ode>
<bullet><friction>1.000000e+00</friction>
<friction2>1.000000e+00</friction2></bullet></friction></surface>
<geometry><box><size>9.000000e-02 9.000000e-02 4.500000e-02</size></box></geometry></collision>
<sensor type="imu" name="node-0-imu_sensor"><pose>-2.122954e-03 2.122954e-03 -6.593184e-21 0.000000e+00 -0.000000e+00 0.000000e+00</pose>
<update_rate>8.000000e+00</update_rate>
<always_on>1</always_on></sensor>
<visual name="component_node-1__root_visual"><pose>-2.122954e-03 -4.362705e-02 -6.593184e-21 3.141593e+00 -0.000000e+00 -1.570796e+00</pose>
<material><ambient>0.55 0.16 0.65 1.00</ambient><diffuse>0.55 0.16 0.65 1.00</diffuse><specular>0.1 0.1 0.1 1.00</specular></material>
<geometry><box><size>1.500000e-03 3.400000e-02 3.400000e-02</size></box></geometry></visual>
<collision name="component_node-1__root_collision"><pose>-2.122954e-03 -4.362705e-02 -6.593184e-21 3.141593e+00 -0.000000e+00 -1.570796e+00</pose>
<surface><contact><ode><kd>3.333333e+06</kd><kp>9.000000e+04</kp></ode></contact>
<friction><ode><mu>1.000000e+00</mu>
<mu2>1.000000e+00</mu2>
<slip1>1.000000e-02</slip1>
<slip2>1.000000e-02</slip2></ode>
<bullet><friction>1.000000e+00</friction>
<friction2>1.000000e+00</friction2></bullet></friction></surface>
<geometry><box><size>1.500000e-03 3.400000e-02 3.400000e-02</size></box></geometry></collision>
<visual name="component_node-1__frame_frame_visual"><pose>-2.122954e-03 -5.347705e-02 -6.593184e-21 3.141593e+00 -0.000000e+00 -1.570796e+00</pose>
<material><ambient>0.55 0.16 0.65 1.00</ambient><diffuse>0.55 0.16 0.65 1.00</diffuse><specular>0.1 0.1 0.1 1.00</specular></material>
<geometry><mesh><uri>model://rg_robot/meshes/ActiveHinge_Frame.dae</uri></mesh></geometry></visual>
<collision name="component_node-1__frame_collision"><pose>-2.122954e-03 -5.347705e-02 -6.593184e-21 3.141593e+00 -0.000000e+00 -1.570796e+00</pose>
<surface><contact><ode><kd>3.333333e+06</kd><kp>9.000000e+04</kp></ode></contact>
<friction><ode><mu>1.000000e+00</mu>
<mu2>1.000000e+00</mu2>
<slip1>1.000000e-02</slip1>
<slip2>1.000000e-02</slip2></ode>
<bullet><friction>1.000000e+00</friction>
<friction2>1.000000e+00</friction2></bullet></friction></surface>
<geometry><box><size>1.800000e-02 3.400000e-02 1.000000e-02</size></box></geometry></collision>
<collision name="component_node-3__slot_b_collision"><pose>-2.122954e-03 4.787295e-02 3.504018e-20 -1.570796e+00 5.551115e-17 -1.570796e+00</pose>
<surface><contact><ode><kd>3.333333e+06</kd><kp>9.000000e+04</kp></ode></contact>
<friction><ode><mu>1.000000e+00</mu>
<mu2>1.000000e+00</mu2>
<slip1>1.000000e-02</slip1>
<slip2>1.000000e-02</slip2></ode>
<bullet><friction>1.000000e+00</friction>
<friction2>1.000000e+00</friction2></bullet></friction></surface>
<geometry><box><size>1.500000e-03 3.400000e-02 3.400000e-02</size></box></geometry></collision>
<visual name="component_node-3__conn_b_conn_b_visual"><pose>-2.122954e-03 5.897295e-02 6.512140e-19 -1.570796e+00 -1.665335e-16 1.570796e+00</pose>
<material><ambient>0.55 0.16 0.65 1.00</ambient><diffuse>0.55 0.16 0.65 1.00</diffuse><specular>0.1 0.1 0.1 1.00</specular></material>
<geometry><mesh><uri>model://rg_robot/meshes/PassiveHinge.dae</uri></mesh></geometry></visual>
<collision name="component_node-3__conn_b_collision"><pose>-2.122954e-03 5.897295e-02 6.512140e-19 -1.570796e+00 5.551115e-17 -1.570796e+00</pose>
<surface><contact><ode><kd>3.333333e+06</kd><kp>9.000000e+04</kp></ode></contact>
<friction><ode><mu>1.000000e+00</mu>
<mu2>1.000000e+00</mu2>
<slip1>1.000000e-02</slip1>
<slip2>1.000000e-02</slip2></ode>
<bullet><friction>1.000000e+00</friction>
<friction2>1.000000e+00</friction2></bullet></friction></surface>
<geometry><box><size>2.050000e-02 2.000000e-03 2.000000e-02</size></box></geometry></collision>
<visual name="component_node-4__root_visual"><pose>4.362705e-02 2.122954e-03 -6.593184e-21 1.570796e+00 -0.000000e+00 0.000000e+00</pose>
<material><ambient>0.55 0.16 0.65 1.00</ambient><diffuse>0.55 0.16 0.65 1.00</diffuse><specular>0.1 0.1 0.1 1.00</specular></material>
<geometry><box><size>1.500000e-03 3.400000e-02 3.400000e-02</size></box></geometry></visual>
<collision name="component_node-4__root_collision"><pose>4.362705e-02 2.122954e-03 -6.593184e-21 1.570796e+00 -0.000000e+00 0.000000e+00</pose>
<surface><contact><ode><kd>3.333333e+06</kd><kp>9.000000e+04</kp></ode></contact>
<friction><ode><mu>1.000000e+00</mu>
<mu2>1.000000e+00</mu2>
<slip1>1.000000e-02</slip1>
<slip2>1.000000e-02</slip2></ode>
<bullet><friction>1.000000e+00</friction>
<friction2>1.000000e+00</friction2></bullet></friction></surface>
<geometry><box><size>1.500000e-03 3.400000e-02 3.400000e-02</size></box></geometry></collision>
<visual name="component_node-4__frame_frame_visual"><pose>5.347705e-02 2.122954e-03 -6.593184e-21 1.570796e+00 -0.000000e+00 0.000000e+00</pose>
<material><ambient>0.55 0.16 0.65 1.00</ambient><diffuse>0.55 0.16 0.65 1.00</diffuse><specular>0.1 0.1 0.1 1.00</specular></material>
<geometry><mesh><uri>model://rg_robot/meshes/ActiveHinge_Frame.dae</uri></mesh></geometry></visual>
<collision name="component_node-4__frame_collision"><pose>5.347705e-02 2.122954e-03 -6.593184e-21 1.570796e+00 -0.000000e+00 0.000000e+00</pose>
<surface><contact><ode><kd>3.333333e+06</kd><kp>9.000000e+04</kp></ode></contact>
<friction><ode><mu>1.000000e+00</mu>
<mu2>1.000000e+00</mu2>
<slip1>1.000000e-02</slip1>
<slip2>1.000000e-02</slip2></ode>
<bullet><friction>1.000000e+00</friction>
<friction2>1.000000e+00</friction2></bullet></friction></surface>
<geometry><box><size>1.800000e-02 3.400000e-02 1.000000e-02</size></box></geometry></collision>
<collision name="component_node-21__slot_b_collision"><pose>-4.787295e-02 2.122954e-03 -6.593184e-21 1.570796e+00 -0.000000e+00 0.000000e+00</pose>
<surface><contact><ode><kd>3.333333e+06</kd><kp>9.000000e+04</kp></ode></contact>
<friction><ode><mu>1.000000e+00</mu>
<mu2>1.000000e+00</mu2>
<slip1>1.000000e-02</slip1>
<slip2>1.000000e-02</slip2></ode>
<bullet><friction>1.000000e+00</friction>
<friction2>1.000000e+00</friction2></bullet></friction></surface>
<geometry><box><size>1.500000e-03 3.400000e-02 3.400000e-02</size></box></geometry></collision>
<visual name="component_node-21__conn_b_conn_b_visual"><pose>-5.897295e-02 2.122954e-03 -6.593184e-21 1.570796e+00 -1.224647e-16 -3.141593e+00</pose>
<material><ambient>0.55 0.16 0.65 1.00</ambient><diffuse>0.55 0.16 0.65 1.00</diffuse><specular>0.1 0.1 0.1 1.00</specular></material>
<geometry><mesh><uri>model://rg_robot/meshes/PassiveHinge.dae</uri></mesh></geometry></visual>
<collision name="component_node-21__conn_b_collision"><pose>-5.897295e-02 2.122954e-03 -6.593184e-21 1.570796e+00 -0.000000e+00 0.000000e+00</pose>
<surface><contact><ode><kd>3.333333e+06</kd><kp>9.000000e+04</kp></ode></contact>
<friction><ode><mu>1.000000e+00</mu>
<mu2>1.000000e+00</mu2>
<slip1>1.000000e-02</slip1>
<slip2>1.000000e-02</slip2></ode>
<bullet><friction>1.000000e+00</friction>
<friction2>1.000000e+00</friction2></bullet></friction></surface>
<geometry><box><size>2.050000e-02 2.000000e-03 2.000000e-02</size></box></geometry></collision>
<inertial><mass>1.124000e-01</mass><inertia><ixx>1.040497e-04</ixx><ixy>-5.065792e-07</ixy><ixz>7.606625e-23</ixz><iyy>1.041553e-04</iyy><iyz>-1.212371e-22</iyz><izz>1.741096e-04</izz></inertia></inertial>
<self_collide>True</self_collide></link>
<link name="link_component_node-1__servo"><pose>-1.560156e-19 -7.656579e-02 2.340233e-19 0.000000e+00 -0.000000e+00 0.000000e+00</pose>
<visual name="component_node-1__servo_servo_visual"><pose>1.560156e-19 7.715789e-03 -2.340233e-19 3.141593e+00 -0.000000e+00 -1.570796e+00</pose>
<material><ambient>0.55 0.16 0.65 1.00</ambient><diffuse>0.55 0.16 0.65 1.00</diffuse><specular>0.1 0.1 0.1 1.00</specular></material>
<geometry><mesh><uri>model://rg_robot/meshes/ActiveCardanHinge_Servo_Holder.dae</uri></mesh></geometry></visual>
<collision name="component_node-1__servo_collision"><pose>1.560156e-19 7.715789e-03 -2.340233e-19 3.141593e+00 -0.000000e+00 -1.570796e+00</pose>
<surface><contact><ode><kd>3.333333e+06</kd><kp>9.000000e+04</kp></ode></contact>
<friction><ode><mu>1.000000e+00</mu>
<mu2>1.000000e+00</mu2>
<slip1>1.000000e-02</slip1>
<slip2>1.000000e-02</slip2></ode>
<bullet><friction>1.000000e+00</friction>
<friction2>1.000000e+00</friction2></bullet></friction></surface>
<geometry><box><size>2.450000e-02 3.400000e-02 1.000000e-02</size></box></geometry></collision>
<collision name="component_node-1__tail_collision"><pose>1.560156e-19 -5.384211e-03 -2.340233e-19 3.141593e+00 -0.000000e+00 -1.570796e+00</pose>
<surface><contact><ode><kd>3.333333e+06</kd><kp>9.000000e+04</kp></ode></contact>
<friction><ode><mu>1.000000e+00</mu>
<mu2>1.000000e+00</mu2>
<slip1>1.000000e-02</slip1>
<slip2>1.000000e-02</slip2></ode>
<bullet><friction>1.000000e+00</friction>
<friction2>1.000000e+00</friction2></bullet></friction></surface>
<geometry><box><size>1.500000e-03 3.400000e-02 3.400000e-02</size></box></geometry></collision>
<collision name="component_node-2__slot_b_collision"><pose>-1.051790e-20 -6.884211e-03 1.577685e-20 -1.570796e+00 2.220446e-16 1.570796e+00</pose>
<surface><contact><ode><kd>3.333333e+06</kd><kp>9.000000e+04</kp></ode></contact>
<friction><ode><mu>1.000000e+00</mu>
<mu2>1.000000e+00</mu2>
<slip1>1.000000e-02</slip1>
<slip2>1.000000e-02</slip2></ode>
<bullet><friction>1.000000e+00</friction>
<friction2>1.000000e+00</friction2></bullet></friction></surface>
<geometry><box><size>1.500000e-03 3.400000e-02 3.400000e-02</size></box></geometry></collision>
<visual name="component_node-2__conn_b_conn_b_visual"><pose>-2.475213e-18 -1.798421e-02 3.712820e-18 -1.570796e+00 -3.330669e-16 -1.570796e+00</pose>
<material><ambient>0.55 0.16 0.65 1.00</ambient><diffuse>0.55 0.16 0.65 1.00</diffuse><specular>0.1 0.1 0.1 1.00</specular></material>
<geometry><mesh><uri>model://rg_robot/meshes/PassiveHinge.dae</uri></mesh></geometry></visual>
<collision name="component_node-2__conn_b_collision"><pose>-2.475213e-18 -1.798421e-02 3.712820e-18 -1.570796e+00 2.220446e-16 1.570796e+00</pose>
<surface><contact><ode><kd>3.333333e+06</kd><kp>9.000000e+04</kp></ode></contact>
<friction><ode><mu>1.000000e+00</mu>
<mu2>1.000000e+00</mu2>
<slip1>1.000000e-02</slip1>
<slip2>1.000000e-02</slip2></ode>
<bullet><friction>1.000000e+00</friction>
<friction2>1.000000e+00</friction2></bullet></friction></surface>
<geometry><box><size>2.050000e-02 2.000000e-03 2.000000e-02</size></box></geometry></collision>
<inertial><mass>1.900000e-02</mass><inertia><ixx>2.586174e-06</ixx><ixy>-1.003275e-22</ixy><ixz>1.550336e-22</ixz><iyy>2.709667e-06</iyy><iyz>9.746659e-23</iyz><izz>3.411174e-06</izz></inertia></inertial>
<self_collide>True</self_collide></link>
<link name="link_component_node-2__conn_a"><pose>-7.938095e-18 -1.184500e-01 1.190714e-17 0.000000e+00 -0.000000e+00 0.000000e+00</pose>
<visual name="component_node-2__conn_a_conn_a_visual"><pose>1.559863e-18 6.650000e-03 -2.298162e-18 -1.570796e+00 2.220446e-16 1.570796e+00</pose>
<material><ambient>0.55 0.16 0.65 1.00</ambient><diffuse>0.55 0.16 0.65 1.00</diffuse><specular>0.1 0.1 0.1 1.00</specular></material>
<geometry><mesh><uri>model://rg_robot/meshes/PassiveHinge.dae</uri></mesh></geometry></visual>
<collision name="component_node-2__conn_a_collision"><pose>1.643130e-18 7.400000e-03 -2.464695e-18 -1.570796e+00 2.220446e-16 1.570796e+00</pose>
<surface><contact><ode><kd>3.333333e+06</kd><kp>9.000000e+04</kp></ode></contact>
<friction><ode><mu>1.000000e+00</mu>
<mu2>1.000000e+00</mu2>
<slip1>1.000000e-02</slip1>
<slip2>1.000000e-02</slip2></ode>
<bullet><friction>1.000000e+00</friction>
<friction2>1.000000e+00</friction2></bullet></friction></surface>
<geometry><box><size>2.050000e-02 2.000000e-03 2.000000e-02</size></box></geometry></collision>
<collision name="component_node-2__slot_a_collision"><pose>-8.215650e-19 -3.700000e-03 1.232348e-18 -1.570796e+00 2.220446e-16 1.570796e+00</pose>
<surface><contact><ode><kd>3.333333e+06</kd><kp>9.000000e+04</kp></ode></contact>
<friction><ode><mu>1.000000e+00</mu>
<mu2>1.000000e+00</mu2>
<slip1>1.000000e-02</slip1>
<slip2>1.000000e-02</slip2></ode>
<bullet><friction>1.000000e+00</friction>
<friction2>1.000000e+00</friction2></bullet></friction></surface>
<geometry><box><size>1.500000e-03 3.400000e-02 3.400000e-02</size></box></geometry></collision>
<inertial><mass>3.000000e-03</mass><inertia><ixx>3.105358e-07</ixx><ixy>-6.895281e-23</ixy><ixz>5.804153e-23</ixz><iyy>4.190000e-07</iyy><iyz>5.040450e-23</iyz><izz>3.435358e-07</izz></inertia></inertial>
<self_collide>True</self_collide></link>
<joint type="revolute" name="joint_link_component_node-2__conn_a_link_component_node-1__servo"><pose>-4.307081e-18 -2.623421e-02 6.460622e-18 -1.570796e+00 3.330669e-16 1.570796e+00</pose>
<parent>link_component_node-2__conn_a</parent>
<child>link_component_node-1__servo</child>
<axis><xyz>0.000000e+00 0.000000e+00 1.000000e+00</xyz>
<use_parent_model_frame>0</use_parent_model_frame>
<limit><lower>-1.047198e+00</lower>
<upper>1.047198e+00</upper></limit></axis></joint>
<joint type="revolute" name="joint_link_component_node-1__servo_link_component_node-0__box"><pose>-2.122954e-03 -5.847705e-02 -6.593184e-21 3.141593e+00 -0.000000e+00 -1.570796e+00</pose>
<parent>link_component_node-1__servo</parent>
<child>link_component_node-0__box</child>
<axis><xyz>0.000000e+00 1.000000e+00 0.000000e+00</xyz>
<use_parent_model_frame>0</use_parent_model_frame>
<limit><lower>-7.853982e-01</lower>
<upper>7.853982e-01</upper>
<effort>1.765800e-01</effort>
<velocity>5.235988e+00</velocity></limit></axis></joint>
<link name="link_component_node-3__conn_a"><pose>-7.938095e-18 8.075000e-02 1.984524e-18 0.000000e+00 -0.000000e+00 0.000000e+00</pose>
<visual name="component_node-3__conn_a_conn_a_visual"><pose>1.268430e-18 -6.650000e-03 -5.773160e-19 -1.570796e+00 5.551115e-17 -1.570796e+00</pose>
<material><ambient>0.55 0.16 0.65 1.00</ambient><diffuse>0.55 0.16 0.65 1.00</diffuse><specular>0.1 0.1 0.1 1.00</specular></material>
<geometry><mesh><uri>model://rg_robot/meshes/PassiveHinge.dae</uri></mesh></geometry></visual>
<collision name="component_node-3__conn_a_collision"><pose>1.643130e-18 -7.400000e-03 -4.107825e-19 -1.570796e+00 5.551115e-17 -1.570796e+00</pose>
<surface><contact><ode><kd>3.333333e+06</kd><kp>9.000000e+04</kp></ode></contact>
<friction><ode><mu>1.000000e+00</mu>
<mu2>1.000000e+00</mu2>
<slip1>1.000000e-02</slip1>
<slip2>1.000000e-02</slip2></ode>
<bullet><friction>1.000000e+00</friction>
<friction2>1.000000e+00</friction2></bullet></friction></surface>
<geometry><box><size>2.050000e-02 2.000000e-03 2.000000e-02</size></box></geometry></collision>
<collision name="component_node-3__slot_a_collision"><pose>-8.215650e-19 3.700000e-03 2.053913e-19 -1.570796e+00 5.551115e-17 -1.570796e+00</pose>
<surface><contact><ode><kd>3.333333e+06</kd><kp>9.000000e+04</kp></ode></contact>
<friction><ode><mu>1.000000e+00</mu>
<mu2>1.000000e+00</mu2>
<slip1>1.000000e-02</slip1>
<slip2>1.000000e-02</slip2></ode>
<bullet><friction>1.000000e+00</friction>
<friction2>1.000000e+00</friction2></bullet></friction></surface>
<geometry><box><size>1.500000e-03 3.400000e-02 3.400000e-02</size></box></geometry></collision>
<inertial><mass>3.000000e-03</mass><inertia><ixx>3.105358e-07</ixx><ixy>-8.747646e-23</ixy><ixz>6.156071e-23</ixz><iyy>4.190000e-07</iyy><iyz>-6.836282e-23</iyz><izz>3.435358e-07</izz></inertia></inertial>
<self_collide>True</self_collide></link>
<joint type="revolute" name="joint_link_component_node-3__conn_a_link_component_node-0__box"><pose>-2.122954e-03 6.722295e-02 1.109181e-18 -1.570796e+00 5.551115e-17 -1.570796e+00</pose>
<parent>link_component_node-3__conn_a</parent>
<child>link_component_node-0__box</child>
<axis><xyz>0.000000e+00 0.000000e+00 1.000000e+00</xyz>
<use_parent_model_frame>0</use_parent_model_frame>
<limit><lower>-1.047198e+00</lower>
<upper>1.047198e+00</upper></limit></axis></joint>
<link name="link_component_node-4__servo"><pose>7.807479e-02 0.000000e+00 0.000000e+00 0.000000e+00 -0.000000e+00 0.000000e+00</pose>
<visual name="component_node-4__servo_servo_visual"><pose>-9.224793e-03 0.000000e+00 0.000000e+00 1.570796e+00 -0.000000e+00 0.000000e+00</pose>
<material><ambient>0.55 0.16 0.65 1.00</ambient><diffuse>0.55 0.16 0.65 1.00</diffuse><specular>0.1 0.1 0.1 1.00</specular></material>
<geometry><mesh><uri>model://rg_robot/meshes/ActiveCardanHinge_Servo_Holder.dae</uri></mesh></geometry></visual>
<collision name="component_node-4__servo_collision"><pose>-9.224793e-03 0.000000e+00 0.000000e+00 1.570796e+00 -0.000000e+00 0.000000e+00</pose>
<surface><contact><ode><kd>3.333333e+06</kd><kp>9.000000e+04</kp></ode></contact>
<friction><ode><mu>1.000000e+00</mu>
<mu2>1.000000e+00</mu2>
<slip1>1.000000e-02</slip1>
<slip2>1.000000e-02</slip2></ode>
<bullet><friction>1.000000e+00</friction>
<friction2>1.000000e+00</friction2></bullet></friction></surface>
<geometry><box><size>2.450000e-02 3.400000e-02 1.000000e-02</size></box></geometry></collision>
<collision name="component_node-4__tail_collision"><pose>3.875207e-03 0.000000e+00 0.000000e+00 1.570796e+00 -0.000000e+00 0.000000e+00</pose>
<surface><contact><ode><kd>3.333333e+06</kd><kp>9.000000e+04</kp></ode></contact>
<friction><ode><mu>1.000000e+00</mu>
<mu2>1.000000e+00</mu2>
<slip1>1.000000e-02</slip1>
<slip2>1.000000e-02</slip2></ode>
<bullet><friction>1.000000e+00</friction>
<friction2>1.000000e+00</friction2></bullet></friction></surface>
<geometry><box><size>1.500000e-03 3.400000e-02 3.400000e-02</size></box></geometry></collision>
<visual name="component_node-5__root_visual"><pose>5.375207e-03 0.000000e+00 0.000000e+00 -1.570796e+00 0.000000e+00 0.000000e+00</pose>
<material><ambient>0.84 0.05 0.24 1.00</ambient><diffuse>0.84 0.05 0.24 1.00</diffuse><specular>0.1 0.1 0.1 1.00</specular></material>
<geometry><box><size>1.500000e-03 3.400000e-02 3.400000e-02</size></box></geometry></visual>
<collision name="component_node-5__root_collision"><pose>5.375207e-03 0.000000e+00 0.000000e+00 -1.570796e+00 0.000000e+00 0.000000e+00</pose>
<surface><contact><ode><kd>3.333333e+06</kd><kp>9.000000e+04</kp></ode></contact>
<friction><ode><mu>1.000000e+00</mu>
<mu2>1.000000e+00</mu2>
<slip1>1.000000e-02</slip1>
<slip2>1.000000e-02</slip2></ode>
<bullet><friction>1.000000e+00</friction>
<friction2>1.000000e+00</friction2></bullet></friction></surface>
<geometry><box><size>1.500000e-03 3.400000e-02 3.400000e-02</size></box></geometry></collision>
<visual name="component_node-5__frame_frame_visual"><pose>1.522521e-02 0.000000e+00 0.000000e+00 -1.570796e+00 0.000000e+00 0.000000e+00</pose>
<material><ambient>0.84 0.05 0.24 1.00</ambient><diffuse>0.84 0.05 0.24 1.00</diffuse><specular>0.1 0.1 0.1 1.00</specular></material>
<geometry><mesh><uri>model://rg_robot/meshes/ActiveHinge_Frame.dae</uri></mesh></geometry></visual>
<collision name="component_node-5__frame_collision"><pose>1.522521e-02 0.000000e+00 0.000000e+00 -1.570796e+00 0.000000e+00 0.000000e+00</pose>
<surface><contact><ode><kd>3.333333e+06</kd><kp>9.000000e+04</kp></ode></contact>
<friction><ode><mu>1.000000e+00</mu>
<mu2>1.000000e+00</mu2>
<slip1>1.000000e-02</slip1>
<slip2>1.000000e-02</slip2></ode>
<bullet><friction>1.000000e+00</friction>
<friction2>1.000000e+00</friction2></bullet></friction></surface>
<geometry><box><size>1.800000e-02 3.400000e-02 1.000000e-02</size></box></geometry></collision>
<inertial><mass>2.420000e-02</mass><inertia><ixx>3.764933e-06</ixx><ixy>0.000000e+00</ixy><ixz>0.000000e+00</ixz><iyy>4.167889e-06</iyy><iyz>-4.689582e-23</iyz><izz>3.270289e-06</izz></inertia></inertial>
<self_collide>True</self_collide></link>
<link name="link_component_node-5__servo"><pose>1.347228e-01 -1.535073e-02 6.621453e-18 0.000000e+00 -0.000000e+00 0.000000e+00</pose>
<visual name="component_node-5__servo_servo_visual"><pose>-2.817280e-02 1.535073e-02 -6.621453e-18 -1.570796e+00 0.000000e+00 0.000000e+00</pose>
<material><ambient>0.84 0.05 0.24 1.00</ambient><diffuse>0.84 0.05 0.24 1.00</diffuse><specular>0.1 0.1 0.1 1.00</specular></material>
<geometry><mesh><uri>model://rg_robot/meshes/ActiveCardanHinge_Servo_Holder.dae</uri></mesh></geometry></visual>
<collision name="component_node-5__servo_collision"><pose>-2.817280e-02 1.535073e-02 -6.621453e-18 -1.570796e+00 0.000000e+00 0.000000e+00</pose>
<surface><contact><ode><kd>3.333333e+06</kd><kp>9.000000e+04</kp></ode></contact>
<friction><ode><mu>1.000000e+00</mu>
<mu2>1.000000e+00</mu2>
<slip1>1.000000e-02</slip1>
<slip2>1.000000e-02</slip2></ode>
<bullet><friction>1.000000e+00</friction>
<friction2>1.000000e+00</friction2></bullet></friction></surface>
<geometry><box><size>2.450000e-02 3.400000e-02 1.000000e-02</size></box></geometry></collision>
<collision name="component_node-5__tail_collision"><pose>-1.507280e-02 1.535073e-02 -6.621453e-18 -1.570796e+00 0.000000e+00 0.000000e+00</pose>
<surface><contact><ode><kd>3.333333e+06</kd><kp>9.000000e+04</kp></ode></contact>
<friction><ode><mu>1.000000e+00</mu>
<mu2>1.000000e+00</mu2>
<slip1>1.000000e-02</slip1>
<slip2>1.000000e-02</slip2></ode>
<bullet><friction>1.000000e+00</friction>
<friction2>1.000000e+00</friction2></bullet></friction></surface>
<geometry><box><size>1.500000e-03 3.400000e-02 3.400000e-02</size></box></geometry></collision>
<visual name="component_node-6__tail_visual"><pose>-1.357280e-02 1.535073e-02 -6.724267e-18 1.570796e+00 4.930381e-32 3.141593e+00</pose>
<material><ambient>0.84 0.05 0.24 1.00</ambient><diffuse>0.84 0.05 0.24 1.00</diffuse><specular>0.1 0.1 0.1 1.00</specular></material>
<geometry><box><size>1.500000e-03 3.400000e-02 3.400000e-02</size></box></geometry></visual>
<collision name="component_node-6__tail_collision"><pose>-1.357280e-02 1.535073e-02 -6.724267e-18 1.570796e+00 4.930381e-32 3.141593e+00</pose>
<surface><contact><ode><kd>3.333333e+06</kd><kp>9.000000e+04</kp></ode></contact>
<friction><ode><mu>1.000000e+00</mu>
<mu2>1.000000e+00</mu2>
<slip1>1.000000e-02</slip1>
<slip2>1.000000e-02</slip2></ode>
<bullet><friction>1.000000e+00</friction>
<friction2>1.000000e+00</friction2></bullet></friction></surface>
<geometry><box><size>1.500000e-03 3.400000e-02 3.400000e-02</size></box></geometry></collision>
<visual name="component_node-6__connection_visual"><pose>1.164530e-02 -5.309041e-03 2.324129e-18 1.570796e+00 2.775558e-16 2.455227e+00</pose>
<material><ambient>0.84 0.05 0.24 1.00</ambient><diffuse>0.84 0.05 0.24 1.00</diffuse><specular>0.1 0.1 0.1 1.00</specular></material>
<geometry><box><size>6.370057e-02 2.000000e-02 2.000000e-03</size></box></geometry></visual>
<collision name="component_node-6__connection_collision"><pose>1.164530e-02 -5.309041e-03 2.324129e-18 1.570796e+00 2.775558e-16 2.455227e+00</pose>
<surface><contact><ode><kd>3.333333e+06</kd><kp>9.000000e+04</kp></ode></contact>
<friction><ode><mu>1.000000e+00</mu>
<mu2>1.000000e+00</mu2>
<slip1>1.000000e-02</slip1>
<slip2>1.000000e-02</slip2></ode>
<bullet><friction>1.000000e+00</friction>
<friction2>1.000000e+00</friction2></bullet></friction></surface>
<geometry><box><size>6.370057e-02 2.000000e-02 2.000000e-03</size></box></geometry></collision>
<visual name="component_node-6__root_visual"><pose>3.686339e-02 -2.596881e-02 1.137252e-17 1.570796e+00 2.775558e-16 2.455227e+00</pose>
<material><ambient>0.84 0.05 0.24 1.00</ambient><diffuse>0.84 0.05 0.24 1.00</diffuse><specular>0.1 0.1 0.1 1.00</specular></material>
<geometry><box><size>1.500000e-03 3.400000e-02 3.400000e-02</size></box></geometry></visual>
<collision name="component_node-6__root_collision"><pose>3.686339e-02 -2.596881e-02 1.137252e-17 1.570796e+00 2.775558e-16 2.455227e+00</pose>
<surface><contact><ode><kd>3.333333e+06</kd><kp>9.000000e+04</kp></ode></contact>
<friction><ode><mu>1.000000e+00</mu>
<mu2>1.000000e+00</mu2>
<slip1>1.000000e-02</slip1>
<slip2>1.000000e-02</slip2></ode>
<bullet><friction>1.000000e+00</friction>
<friction2>1.000000e+00</friction2></bullet></friction></surface>
<geometry><box><size>1.500000e-03 3.400000e-02 3.400000e-02</size></box></geometry></collision>
<visual name="component_node-7__root_visual"><pose>3.802372e-02 -2.691941e-02 1.172144e-17 3.141593e+00 -1.876656e-16 -6.863655e-01</pose>
<material><ambient>0.84 0.05 0.24 1.00</ambient><diffuse>0.84 0.05 0.24 1.00</diffuse><specular>0.1 0.1 0.1 1.00</specular></material>
<geometry><box><size>1.500000e-03 3.400000e-02 3.400000e-02</size></box></geometry></visual>
<collision name="component_node-7__root_collision"><pose>3.802372e-02 -2.691941e-02 1.172144e-17 3.141593e+00 -1.876656e-16 -6.863655e-01</pose>
<surface><contact><ode><kd>3.333333e+06</kd><kp>9.000000e+04</kp></ode></contact>
<friction><ode><mu>1.000000e+00</mu>
<mu2>1.000000e+00</mu2>
<slip1>1.000000e-02</slip1>
<slip2>1.000000e-02</slip2></ode>
<bullet><friction>1.000000e+00</friction>
<friction2>1.000000e+00</friction2></bullet></friction></surface>
<geometry><box><size>1.500000e-03 3.400000e-02 3.400000e-02</size></box></geometry></collision>
<visual name="component_node-7__frame_frame_visual"><pose>4.564323e-02 -3.316165e-02 1.356995e-17 3.141593e+00 -1.876656e-16 -6.863655e-01</pose>
<material><ambient>0.84 0.05 0.24 1.00</ambient><diffuse>0.84 0.05 0.24 1.00</diffuse><specular>0.1 0.1 0.1 1.00</specular></material>
<geometry><mesh><uri>model://rg_robot/meshes/ActiveHinge_Frame.dae</uri></mesh></geometry></visual>
<collision name="component_node-7__frame_collision"><pose>4.564323e-02 -3.316165e-02 1.356995e-17 3.141593e+00 -1.876656e-16 -6.863655e-01</pose>
<surface><contact><ode><kd>3.333333e+06</kd><kp>9.000000e+04</kp></ode></contact>
<friction><ode><mu>1.000000e+00</mu>
<mu2>1.000000e+00</mu2>
<slip1>1.000000e-02</slip1>
<slip2>1.000000e-02</slip2></ode>
<bullet><friction>1.000000e+00</friction>
<friction2>1.000000e+00</friction2></bullet></friction></surface>
<geometry><box><size>1.800000e-02 3.400000e-02 1.000000e-02</size></box></geometry></collision>
<inertial><mass>2.747401e-02</mass><inertia><ixx>1.513215e-05</ixx><ixy>1.553081e-05</ixy><ixz>-6.781046e-21</ixz><iyy>2.661684e-05</iyy><iyz>4.323113e-21</iyz><izz>3.682739e-05</izz></inertia></inertial>
<self_collide>True</self_collide></link>
<link name="link_component_node-7__servo"><pose>2.234864e-01 -8.081797e-02 3.304592e-17 0.000000e+00 -0.000000e+00 0.000000e+00</pose>
<visual name="component_node-7__servo_servo_visual"><pose>-3.287080e-02 2.390867e-02 -1.036795e-17 3.141593e+00 -1.876656e-16 -6.863655e-01</pose>
<material><ambient>0.84 0.05 0.24 1.00</ambient><diffuse>0.84 0.05 0.24 1.00</diffuse><specular>0.1 0.1 0.1 1.00</specular></material>
<geometry><mesh><uri>model://rg_robot/meshes/ActiveCardanHinge_Servo_Holder.dae</uri></mesh></geometry></visual>
<collision name="component_node-7__servo_collision"><pose>-3.287080e-02 2.390867e-02 -1.036795e-17 3.141593e+00 -1.876656e-16 -6.863655e-01</pose>
<surface><contact><ode><kd>3.333333e+06</kd><kp>9.000000e+04</kp></ode></contact>
<friction><ode><mu>1.000000e+00</mu>
<mu2>1.000000e+00</mu2>
<slip1>1.000000e-02</slip1>
<slip2>1.000000e-02</slip2></ode>
<bullet><friction>1.000000e+00</friction>
<friction2>1.000000e+00</friction2></bullet></friction></surface>
<geometry><box><size>2.450000e-02 3.400000e-02 1.000000e-02</size></box></geometry></collision>
<collision name="component_node-7__tail_collision"><pose>-2.273724e-02 1.560681e-02 -7.909529e-18 3.141593e+00 -1.876656e-16 -6.863655e-01</pose>
<surface><contact><ode><kd>3.333333e+06</kd><kp>9.000000e+04</kp></ode></contact>
<friction><ode><mu>1.000000e+00</mu>
<mu2>1.000000e+00</mu2>
<slip1>1.000000e-02</slip1>
<slip2>1.000000e-02</slip2></ode>
<bullet><friction>1.000000e+00</friction>
<friction2>1.000000e+00</friction2></bullet></friction></surface>
<geometry><box><size>1.500000e-03 3.400000e-02 3.400000e-02</size></box></geometry></collision>
<visual name="component_node-8__box_visual"><pose>-6.299209e-03 2.140046e-03 -2.164327e-18 2.733879e-16 -4.603410e-16 -2.257162e+00</pose>
<material><ambient>0.84 0.05 0.24 1.00</ambient><diffuse>0.84 0.05 0.24 1.00</diffuse><specular>0.1 0.1 0.1 1.00</specular></material>
<geometry><mesh><uri>model://rg_robot/meshes/FixedBrick.dae</uri></mesh></geometry></visual>
<collision name="component_node-8__box_collision"><pose>-6.299209e-03 2.140046e-03 -2.164327e-18 2.733879e-16 -4.603410e-16 -2.257162e+00</pose>
<surface><contact><ode><kd>3.333333e+06</kd><kp>9.000000e+04</kp></ode></contact>
<friction><ode><mu>1.000000e+00</mu>
<mu2>1.000000e+00</mu2>
<slip1>1.000000e-02</slip1>
<slip2>1.000000e-02</slip2></ode>
<bullet><friction>1.000000e+00</friction>
<friction2>1.000000e+00</friction2></bullet></friction></surface>
<geometry><box><size>4.100000e-02 4.100000e-02 3.550000e-02</size></box></geometry></collision>
<visual name="component_node-9__box_visual"><pose>2.541652e-02 -2.384288e-02 1.078992e-17 3.434788e-16 3.585266e-16 2.455227e+00</pose>
<material><ambient>0.84 0.05 0.24 1.00</ambient><diffuse>0.84 0.05 0.24 1.00</diffuse><specular>0.1 0.1 0.1 1.00</specular></material>
<geometry><mesh><uri>model://rg_robot/meshes/FixedBrick.dae</uri></mesh></geometry></visual>
<collision name="component_node-9__box_collision"><pose>2.541652e-02 -2.384288e-02 1.078992e-17 3.434788e-16 3.585266e-16 2.455227e+00</pose>
<surface><contact><ode><kd>3.333333e+06</kd><kp>9.000000e+04</kp></ode></contact>
<friction><ode><mu>1.000000e+00</mu>
<mu2>1.000000e+00</mu2>
<slip1>1.000000e-02</slip1>
<slip2>1.000000e-02</slip2></ode>
<bullet><friction>1.000000e+00</friction>
<friction2>1.000000e+00</friction2></bullet></friction></surface>
<geometry><box><size>4.100000e-02 4.100000e-02 3.550000e-02</size></box></geometry></collision>
<visual name="component_node-10__root_visual"><pose>3.888328e-02 -7.404847e-03 3.831872e-18 1.570796e+00 -1.110223e-16 8.844309e-01</pose>
<material><ambient>0.55 0.16 0.65 1.00</ambient><diffuse>0.55 0.16 0.65 1.00</diffuse><specular>0.1 0.1 0.1 1.00</specular></material>
<geometry><box><size>1.500000e-03 3.400000e-02 3.400000e-02</size></box></geometry></visual>
<collision name="component_node-10__root_collision"><pose>3.888328e-02 -7.404847e-03 3.831872e-18 1.570796e+00 -1.110223e-16 8.844309e-01</pose>
<surface><contact><ode><kd>3.333333e+06</kd><kp>9.000000e+04</kp></ode></contact>
<friction><ode><mu>1.000000e+00</mu>
<mu2>1.000000e+00</mu2>
<slip1>1.000000e-02</slip1>
<slip2>1.000000e-02</slip2></ode>
<bullet><friction>1.000000e+00</friction>
<friction2>1.000000e+00</friction2></bullet></friction></surface>
<geometry><box><size>1.500000e-03 3.400000e-02 3.400000e-02</size></box></geometry></collision>
<visual name="component_node-10__frame_frame_visual"><pose>4.512552e-02 2.146644e-04 4.925442e-18 1.570796e+00 -1.110223e-16 8.844309e-01</pose>
<material><ambient>0.55 0.16 0.65 1.00</ambient><diffuse>0.55 0.16 0.65 1.00</diffuse><specular>0.1 0.1 0.1 1.00</specular></material>
<geometry><mesh><uri>model://rg_robot/meshes/ActiveHinge_Frame.dae</uri></mesh></geometry></visual>
<collision name="component_node-10__frame_collision"><pose>4.512552e-02 2.146644e-04 4.925442e-18 1.570796e+00 -1.110223e-16 8.844309e-01</pose>
<surface><contact><ode><kd>3.333333e+06</kd><kp>9.000000e+04</kp></ode></contact>
<friction><ode><mu>1.000000e+00</mu>
<mu2>1.000000e+00</mu2>
<slip1>1.000000e-02</slip1>
<slip2>1.000000e-02</slip2></ode>
<bullet><friction>1.000000e+00</friction>
<friction2>1.000000e+00</friction2></bullet></friction></surface>
<geometry><box><size>1.800000e-02 3.400000e-02 1.000000e-02</size></box></geometry></collision>
<collision name="component_node-19__slot_b_collision"><pose>-1.976597e-02 -1.429799e-02 7.617918e-18 3.141593e+00 4.603410e-16 8.844309e-01</pose>
<surface><contact><ode><kd>3.333333e+06</kd><kp>9.000000e+04</kp></ode></contact>
<friction><ode><mu>1.000000e+00</mu>
<mu2>1.000000e+00</mu2>
<slip1>1.000000e-02</slip1>
<slip2>1.000000e-02</slip2></ode>
<bullet><friction>1.000000e+00</friction>
<friction2>1.000000e+00</friction2></bullet></friction></surface>
<geometry><box><size>1.500000e-03 3.400000e-02 3.400000e-02</size></box></geometry></collision>
<visual name="component_node-19__conn_b_conn_b_visual"><pose>-2.680037e-02 -2.288444e-02 1.272770e-17 2.845857e-17 -4.603410e-16 -2.257162e+00</pose>
<material><ambient>0.30 0.59 0.04 1.00</ambient><diffuse>0.30 0.59 0.04 1.00</diffuse><specular>0.1 0.1 0.1 1.00</specular></material>
<geometry><mesh><uri>model://rg_robot/meshes/PassiveHinge.dae</uri></mesh></geometry></visual>
<collision name="component_node-19__conn_b_collision"><pose>-2.680037e-02 -2.288444e-02 1.272770e-17 3.141593e+00 4.603410e-16 8.844309e-01</pose>
<surface><contact><ode><kd>3.333333e+06</kd><kp>9.000000e+04</kp></ode></contact>
<friction><ode><mu>1.000000e+00</mu>
<mu2>1.000000e+00</mu2>
<slip1>1.000000e-02</slip1>
<slip2>1.000000e-02</slip2></ode>
<bullet><friction>1.000000e+00</friction>
<friction2>1.000000e+00</friction2></bullet></friction></surface>
<geometry><box><size>2.050000e-02 2.000000e-03 2.000000e-02</size></box></geometry></collision>
<inertial><mass>4.760000e-02</mass><inertia><ixx>2.227404e-05</ixx><ixy>1.656306e-05</ixy><ixz>-7.762298e-21</ixz><iyy>4.307113e-05</iyy><iyz>6.951967e-21</iyz><izz>5.752978e-05</izz></inertia></inertial>
<self_collide>True</self_collide></link>
<link name="link_component_node-10__servo"><pose>2.828549e-01 -6.321783e-02 3.962010e-17 0.000000e+00 -0.000000e+00 0.000000e+00</pose>
<visual name="component_node-10__servo_servo_visual"><pose>-5.846027e-03 -7.135880e-03 -1.777000e-19 1.570796e+00 -1.110223e-16 8.844309e-01</pose>
<material><ambient>0.55 0.16 0.65 1.00</ambient><diffuse>0.55 0.16 0.65 1.00</diffuse><specular>0.1 0.1 0.1 1.00</specular></material>
<geometry><mesh><uri>model://rg_robot/meshes/ActiveCardanHinge_Servo_Holder.dae</uri></mesh></geometry></visual>
<collision name="component_node-10__servo_collision"><pose>-5.846027e-03 -7.135880e-03 -1.777000e-19 1.570796e+00 -1.110223e-16 8.844309e-01</pose>
<surface><contact><ode><kd>3.333333e+06</kd><kp>9.000000e+04</kp></ode></contact>
<friction><ode><mu>1.000000e+00</mu>
<mu2>1.000000e+00</mu2>
<slip1>1.000000e-02</slip1>
<slip2>1.000000e-02</slip2></ode>
<bullet><friction>1.000000e+00</friction>
<friction2>1.000000e+00</friction2></bullet></friction></surface>
<geometry><box><size>2.450000e-02 3.400000e-02 1.000000e-02</size></box></geometry></collision>
<collision name="component_node-10__tail_collision"><pose>2.455834e-03 2.997683e-03 1.276692e-18 1.570796e+00 -1.110223e-16 8.844309e-01</pose>
<surface><contact><ode><kd>3.333333e+06</kd><kp>9.000000e+04</kp></ode></contact>
<friction><ode><mu>1.000000e+00</mu>
<mu2>1.000000e+00</mu2>
<slip1>1.000000e-02</slip1>
<slip2>1.000000e-02</slip2></ode>
<bullet><friction>1.000000e+00</friction>
<friction2>1.000000e+00</friction2></bullet></friction></surface>
<geometry><box><size>1.500000e-03 3.400000e-02 3.400000e-02</size></box></geometry></collision>
<visual name="component_node-11__root_visual"><pose>3.406429e-03 4.158015e-03 -8.148053e-19 -1.570796e+00 1.110223e-16 8.844309e-01</pose>
<material><ambient>0.84 0.05 0.24 1.00</ambient><diffuse>0.84 0.05 0.24 1.00</diffuse><specular>0.1 0.1 0.1 1.00</specular></material>
<geometry><box><size>1.500000e-03 3.400000e-02 3.400000e-02</size></box></geometry></visual>
<collision name="component_node-11__root_collision"><pose>3.406429e-03 4.158015e-03 -8.148053e-19 -1.570796e+00 1.110223e-16 8.844309e-01</pose>
<surface><contact><ode><kd>3.333333e+06</kd><kp>9.000000e+04</kp></ode></contact>
<friction><ode><mu>1.000000e+00</mu>
<mu2>1.000000e+00</mu2>
<slip1>1.000000e-02</slip1>
<slip2>1.000000e-02</slip2></ode>
<bullet><friction>1.000000e+00</friction>
<friction2>1.000000e+00</friction2></bullet></friction></surface>
<geometry><box><size>1.500000e-03 3.400000e-02 3.400000e-02</size></box></geometry></collision>
<visual name="component_node-11__frame_frame_visual"><pose>9.648668e-03 1.177753e-02 -1.361590e-18 -1.570796e+00 1.110223e-16 8.844309e-01</pose>
<material><ambient>0.84 0.05 0.24 1.00</ambient><diffuse>0.84 0.05 0.24 1.00</diffuse><specular>0.1 0.1 0.1 1.00</specular></material>
<geometry><mesh><uri>model://rg_robot/meshes/ActiveHinge_Frame.dae</uri></mesh></geometry></visual>
<collision name="component_node-11__frame_collision"><pose>9.648668e-03 1.177753e-02 -1.361590e-18 -1.570796e+00 1.110223e-16 8.844309e-01</pose>
<surface><contact><ode><kd>3.333333e+06</kd><kp>9.000000e+04</kp></ode></contact>
<friction><ode><mu>1.000000e+00</mu>
<mu2>1.000000e+00</mu2>
<slip1>1.000000e-02</slip1>
<slip2>1.000000e-02</slip2></ode>
<bullet><friction>1.000000e+00</friction>
<friction2>1.000000e+00</friction2></bullet></friction></surface>
<geometry><box><size>1.800000e-02 3.400000e-02 1.000000e-02</size></box></geometry></collision>
<inertial><mass>2.420000e-02</mass><inertia><ixx>4.006057e-06</ixx><ixy>-1.975389e-07</ixy><ixz>5.247332e-23</ixz><iyy>3.926766e-06</iyy><iyz>-1.041196e-22</iyz><izz>3.270289e-06</izz></inertia></inertial>
<self_collide>True</self_collide></link>
<link name="link_component_node-11__servo"><pose>3.300456e-01 -3.156051e-02 4.399057e-17 0.000000e+00 -0.000000e+00 0.000000e+00</pose>
<visual name="component_node-11__servo_servo_visual"><pose>-2.914513e-02 -9.630190e-03 -6.467580e-18 -1.570796e+00 1.110223e-16 8.844309e-01</pose>
<material><ambient>0.84 0.05 0.24 1.00</ambient><diffuse>0.84 0.05 0.24 1.00</diffuse><specular>0.1 0.1 0.1 1.00</specular></material>
<geometry><mesh><uri>model://rg_robot/meshes/ActiveCardanHinge_Servo_Holder.dae</uri></mesh></geometry></visual>
<collision name="component_node-11__servo_collision"><pose>-2.914513e-02 -9.630190e-03 -6.467580e-18 -1.570796e+00 1.110223e-16 8.844309e-01</pose>
<surface><contact><ode><kd>3.333333e+06</kd><kp>9.000000e+04</kp></ode></contact>
<friction><ode><mu>1.000000e+00</mu>
<mu2>1.000000e+00</mu2>
<slip1>1.000000e-02</slip1>
<slip2>1.000000e-02</slip2></ode>
<bullet><friction>1.000000e+00</friction>
<friction2>1.000000e+00</friction2></bullet></friction></surface>
<geometry><box><size>2.450000e-02 3.400000e-02 1.000000e-02</size></box></geometry></collision>
<collision name="component_node-11__tail_collision"><pose>-2.084327e-02 5.033730e-04 -7.194776e-18 -1.570796e+00 1.110223e-16 8.844309e-01</pose>
<surface><contact><ode><kd>3.333333e+06</kd><kp>9.000000e+04</kp></ode></contact>
<friction><ode><mu>1.000000e+00</mu>
<mu2>1.000000e+00</mu2>
<slip1>1.000000e-02</slip1>
<slip2>1.000000e-02</slip2></ode>
<bullet><friction>1.000000e+00</friction>
<friction2>1.000000e+00</friction2></bullet></friction></surface>
<geometry><box><size>1.500000e-03 3.400000e-02 3.400000e-02</size></box></geometry></collision>
<visual name="component_node-12__tail_visual"><pose>-1.989267e-02 1.663705e-03 -9.107033e-18 1.570796e+00 -2.220446e-16 -2.257162e+00</pose>
<material><ambient>0.84 0.05 0.24 1.00</ambient><diffuse>0.84 0.05 0.24 1.00</diffuse><specular>0.1 0.1 0.1 1.00</specular></material>
<geometry><box><size>1.500000e-03 3.400000e-02 3.400000e-02</size></box></geometry></visual>
<collision name="component_node-12__tail_collision"><pose>-1.989267e-02 1.663705e-03 -9.107033e-18 1.570796e+00 -2.220446e-16 -2.257162e+00</pose>
<surface><contact><ode><kd>3.333333e+06</kd><kp>9.000000e+04</kp></ode></contact>
<friction><ode><mu>1.000000e+00</mu>
<mu2>1.000000e+00</mu2>
<slip1>1.000000e-02</slip1>
<slip2>1.000000e-02</slip2></ode>
<bullet><friction>1.000000e+00</friction>
<friction2>1.000000e+00</friction2></bullet></friction></surface>
<geometry><box><size>1.500000e-03 3.400000e-02 3.400000e-02</size></box></geometry></collision>
<visual name="component_node-12__connection_visual"><pose>1.126709e-02 4.809118e-03 1.323996e-18 1.570796e+00 3.261280e-16 -3.040989e+00</pose>
<material><ambient>0.84 0.05 0.24 1.00</ambient><diffuse>0.84 0.05 0.24 1.00</diffuse><specular>0.1 0.1 0.1 1.00</specular></material>
<geometry><box><size>6.113624e-02 2.000000e-02 2.000000e-03</size></box></geometry></visual>
<collision name="component_node-12__connection_collision"><pose>1.126709e-02 4.809118e-03 1.323996e-18 1.570796e+00 3.261280e-16 -3.040989e+00</pose>
<surface><contact><ode><kd>3.333333e+06</kd><kp>9.000000e+04</kp></ode></contact>
<friction><ode><mu>1.000000e+00</mu>
<mu2>1.000000e+00</mu2>
<slip1>1.000000e-02</slip1>
<slip2>1.000000e-02</slip2></ode>
<bullet><friction>1.000000e+00</friction>
<friction2>1.000000e+00</friction2></bullet></friction></surface>
<geometry><box><size>6.113624e-02 2.000000e-02 2.000000e-03</size></box></geometry></collision>
<visual name="component_node-12__root_visual"><pose>4.242686e-02 7.954532e-03 1.175503e-17 1.570796e+00 3.261280e-16 -3.040989e+00</pose>
<material><ambient>0.84 0.05 0.24 1.00</ambient><diffuse>0.84 0.05 0.24 1.00</diffuse><specular>0.1 0.1 0.1 1.00</specular></material>
<geometry><box><size>1.500000e-03 3.400000e-02 3.400000e-02</size></box></geometry></visual>
<collision name="component_node-12__root_collision"><pose>4.242686e-02 7.954532e-03 1.175503e-17 1.570796e+00 3.261280e-16 -3.040989e+00</pose>
<surface><contact><ode><kd>3.333333e+06</kd><kp>9.000000e+04</kp></ode></contact>
<friction><ode><mu>1.000000e+00</mu>
<mu2>1.000000e+00</mu2>
<slip1>1.000000e-02</slip1>
<slip2>1.000000e-02</slip2></ode>
<bullet><friction>1.000000e+00</friction>
<friction2>1.000000e+00</friction2></bullet></friction></surface>
<geometry><box><size>1.500000e-03 3.400000e-02 3.400000e-02</size></box></geometry></collision>
<visual name="component_node-13__root_visual"><pose>4.391927e-02 8.105183e-03 1.224962e-17 3.141593e+00 -3.263888e-16 1.006039e-01</pose>
<material><ambient>0.84 0.05 0.24 1.00</ambient><diffuse>0.84 0.05 0.24 1.00</diffuse><specular>0.1 0.1 0.1 1.00</specular></material>
<geometry><box><size>1.500000e-03 3.400000e-02 3.400000e-02</size></box></geometry></visual>
<collision name="component_node-13__root_collision"><pose>4.391927e-02 8.105183e-03 1.224962e-17 3.141593e+00 -3.263888e-16 1.006039e-01</pose>
<surface><contact><ode><kd>3.333333e+06</kd><kp>9.000000e+04</kp></ode></contact>
<friction><ode><mu>1.000000e+00</mu>
<mu2>1.000000e+00</mu2>
<slip1>1.000000e-02</slip1>
<slip2>1.000000e-02</slip2></ode>
<bullet><friction>1.000000e+00</friction>
<friction2>1.000000e+00</friction2></bullet></friction></surface>
<geometry><box><size>1.500000e-03 3.400000e-02 3.400000e-02</size></box></geometry></collision>
<visual name="component_node-13__frame_frame_visual"><pose>5.371947e-02 9.094461e-03 1.546455e-17 3.141593e+00 -3.263888e-16 1.006039e-01</pose>
<material><ambient>0.84 0.05 0.24 1.00</ambient><diffuse>0.84 0.05 0.24 1.00</diffuse><specular>0.1 0.1 0.1 1.00</specular></material>
<geometry><mesh><uri>model://rg_robot/meshes/ActiveHinge_Frame.dae</uri></mesh></geometry></visual>
<collision name="component_node-13__frame_collision"><pose>5.371947e-02 9.094461e-03 1.546455e-17 3.141593e+00 -3.263888e-16 1.006039e-01</pose>
<surface><contact><ode><kd>3.333333e+06</kd><kp>9.000000e+04</kp></ode></contact>
<friction><ode><mu>1.000000e+00</mu>
<mu2>1.000000e+00</mu2>
<slip1>1.000000e-02</slip1>
<slip2>1.000000e-02</slip2></ode>
<bullet><friction>1.000000e+00</friction>
<friction2>1.000000e+00</friction2></bullet></friction></surface>
<geometry><box><size>1.800000e-02 3.400000e-02 1.000000e-02</size></box></geometry></collision>
<inertial><mass>2.742272e-02</mass><inertia><ixx>5.440788e-06</ixx><ixy>-5.661037e-06</ixy><ixz>-7.759247e-21</ixz><iyy>3.356831e-05</iyy><iyz>-1.796107e-21</iyz><izz>3.409091e-05</izz></inertia></inertial>
<self_collide>True</self_collide></link>
<link name="link_component_node-13__servo"><pose>4.249484e-01 -1.585738e-02 7.050156e-17 0.000000e+00 -0.000000e+00 0.000000e+00</pose>
<visual name="component_node-13__servo_servo_visual"><pose>-2.800031e-02 -5.277913e-03 -6.721793e-18 3.141593e+00 -3.263888e-16 1.006039e-01</pose>
<material><ambient>0.84 0.05 0.24 1.00</ambient><diffuse>0.84 0.05 0.24 1.00</diffuse><specular>0.1 0.1 0.1 1.00</specular></material>
<geometry><mesh><uri>model://rg_robot/meshes/ActiveCardanHinge_Servo_Holder.dae</uri></mesh></geometry></visual>
<collision name="component_node-13__servo_collision"><pose>-2.800031e-02 -5.277913e-03 -6.721793e-18 3.141593e+00 -3.263888e-16 1.006039e-01</pose>
<surface><contact><ode><kd>3.333333e+06</kd><kp>9.000000e+04</kp></ode></contact>
<friction><ode><mu>1.000000e+00</mu>
<mu2>1.000000e+00</mu2>
<slip1>1.000000e-02</slip1>
<slip2>1.000000e-02</slip2></ode>
<bullet><friction>1.000000e+00</friction>
<friction2>1.000000e+00</friction2></bullet></friction></surface>
<geometry><box><size>2.450000e-02 3.400000e-02 1.000000e-02</size></box></geometry></collision>
<collision name="component_node-13__tail_collision"><pose>-1.496655e-02 -3.962224e-03 -2.446100e-18 3.141593e+00 -3.263888e-16 1.006039e-01</pose>
<surface><contact><ode><kd>3.333333e+06</kd><kp>9.000000e+04</kp></ode></contact>
<friction><ode><mu>1.000000e+00</mu>
<mu2>1.000000e+00</mu2>
<slip1>1.000000e-02</slip1>
<slip2>1.000000e-02</slip2></ode>
<bullet><friction>1.000000e+00</friction>
<friction2>1.000000e+00</friction2></bullet></friction></surface>
<geometry><box><size>1.500000e-03 3.400000e-02 3.400000e-02</size></box></geometry></collision>
<visual name="component_node-14__box_visual"><pose>6.176005e-03 -1.827995e-03 4.033040e-18 3.041145e-16 -9.224219e-16 -1.470192e+00</pose>
<material><ambient>0.84 0.05 0.24 1.00</ambient><diffuse>0.84 0.05 0.24 1.00</diffuse><specular>0.1 0.1 0.1 1.00</specular></material>
<geometry><mesh><uri>model://rg_robot/meshes/FixedBrick.dae</uri></mesh></geometry></visual>
<collision name="component_node-14__box_collision"><pose>6.176005e-03 -1.827995e-03 4.033040e-18 3.041145e-16 -9.224219e-16 -1.470192e+00</pose>
<surface><contact><ode><kd>3.333333e+06</kd><kp>9.000000e+04</kp></ode></contact>
<friction><ode><mu>1.000000e+00</mu>
<mu2>1.000000e+00</mu2>
<slip1>1.000000e-02</slip1>
<slip2>1.000000e-02</slip2></ode>
<bullet><friction>1.000000e+00</friction>
<friction2>1.000000e+00</friction2></bullet></friction></surface>
<geometry><box><size>4.100000e-02 4.100000e-02 3.550000e-02</size></box></geometry></collision>
<visual name="component_node-15__root_visual"><pose>2.731856e-02 3.062337e-04 1.044433e-17 -1.570796e+00 -2.359224e-16 1.006039e-01</pose>
<material><ambient>0.84 0.05 0.24 1.00</ambient><diffuse>0.84 0.05 0.24 1.00</diffuse><specular>0.1 0.1 0.1 1.00</specular></material>
<geometry><box><size>1.500000e-03 3.400000e-02 3.400000e-02</size></box></geometry></visual>
<collision name="component_node-15__root_collision"><pose>2.731856e-02 3.062337e-04 1.044433e-17 -1.570796e+00 -2.359224e-16 1.006039e-01</pose>
<surface><contact><ode><kd>3.333333e+06</kd><kp>9.000000e+04</kp></ode></contact>
<friction><ode><mu>1.000000e+00</mu>
<mu2>1.000000e+00</mu2>
<slip1>1.000000e-02</slip1>
<slip2>1.000000e-02</slip2></ode>
<bullet><friction>1.000000e+00</friction>
<friction2>1.000000e+00</friction2></bullet></friction></surface>
<geometry><box><size>1.500000e-03 3.400000e-02 3.400000e-02</size></box></geometry></collision>
<visual name="component_node-15__frame_frame_visual"><pose>3.711875e-02 1.295512e-03 1.276817e-17 -1.570796e+00 -2.359224e-16 1.006039e-01</pose>
<material><ambient>0.84 0.05 0.24 1.00</ambient><diffuse>0.84 0.05 0.24 1.00</diffuse><specular>0.1 0.1 0.1 1.00</specular></material>
<geometry><mesh><uri>model://rg_robot/meshes/ActiveHinge_Frame.dae</uri></mesh></geometry></visual>
<collision name="component_node-15__frame_collision"><pose>3.711875e-02 1.295512e-03 1.276817e-17 -1.570796e+00 -2.359224e-16 1.006039e-01</pose>
<surface><contact><ode><kd>3.333333e+06</kd><kp>9.000000e+04</kp></ode></contact>
<friction><ode><mu>1.000000e+00</mu>
<mu2>1.000000e+00</mu2>
<slip1>1.000000e-02</slip1>
<slip2>1.000000e-02</slip2></ode>
<bullet><friction>1.000000e+00</friction>
<friction2>1.000000e+00</friction2></bullet></friction></surface>
<geometry><box><size>1.800000e-02 3.400000e-02 1.000000e-02</size></box></geometry></collision>
<collision name="component_node-16__slot_b_collision"><pose>8.310234e-03 -2.297055e-02 2.394189e-17 -1.570796e+00 1.332268e-15 1.671400e+00</pose>
<surface><contact><ode><kd>3.333333e+06</kd><kp>9.000000e+04</kp></ode></contact>
<friction><ode><mu>1.000000e+00</mu>
<mu2>1.000000e+00</mu2>
<slip1>1.000000e-02</slip1>
<slip2>1.000000e-02</slip2></ode>
<bullet><friction>1.000000e+00</friction>
<friction2>1.000000e+00</friction2></bullet></friction></surface>
<geometry><box><size>1.500000e-03 3.400000e-02 3.400000e-02</size></box></geometry></collision>
<visual name="component_node-16__conn_b_conn_b_visual"><pose>9.425055e-03 -3.401442e-02 3.873006e-17 -1.570796e+00 -1.332268e-15 -1.470192e+00</pose>
<material><ambient>0.55 0.16 0.65 1.00</ambient><diffuse>0.55 0.16 0.65 1.00</diffuse><specular>0.1 0.1 0.1 1.00</specular></material>
<geometry><mesh><uri>model://rg_robot/meshes/PassiveHinge.dae</uri></mesh></geometry></visual>
<collision name="component_node-16__conn_b_collision"><pose>9.425055e-03 -3.401442e-02 3.873006e-17 -1.570796e+00 1.332268e-15 1.671400e+00</pose>
<surface><contact><ode><kd>3.333333e+06</kd><kp>9.000000e+04</kp></ode></contact>
<friction><ode><mu>1.000000e+00</mu>
<mu2>1.000000e+00</mu2>
<slip1>1.000000e-02</slip1>
<slip2>1.000000e-02</slip2></ode>
<bullet><friction>1.000000e+00</friction>
<friction2>1.000000e+00</friction2></bullet></friction></surface>
<geometry><box><size>2.050000e-02 2.000000e-03 2.000000e-02</size></box></geometry></collision>
<visual name="component_node-17__root_visual"><pose>4.041777e-03 1.931456e-02 -1.556843e-17 3.141593e+00 9.224219e-16 1.671400e+00</pose>
<material><ambient>0.55 0.16 0.65 1.00</ambient><diffuse>0.55 0.16 0.65 1.00</diffuse><specular>0.1 0.1 0.1 1.00</specular></material>
<geometry><box><size>1.500000e-03 3.400000e-02 3.400000e-02</size></box></geometry></visual>
<collision name="component_node-17__root_collision"><pose>4.041777e-03 1.931456e-02 -1.556843e-17 3.141593e+00 9.224219e-16 1.671400e+00</pose>
<surface><contact><ode><kd>3.333333e+06</kd><kp>9.000000e+04</kp></ode></contact>
<friction><ode><mu>1.000000e+00</mu>
<mu2>1.000000e+00</mu2>
<slip1>1.000000e-02</slip1>
<slip2>1.000000e-02</slip2></ode>
<bullet><friction>1.000000e+00</friction>
<friction2>1.000000e+00</friction2></bullet></friction></surface>
<geometry><box><size>1.500000e-03 3.400000e-02 3.400000e-02</size></box></geometry></collision>
<visual name="component_node-17__frame_frame_visual"><pose>3.052499e-03 2.911475e-02 -2.465428e-17 3.141593e+00 9.224219e-16 1.671400e+00</pose>
<material><ambient>0.55 0.16 0.65 1.00</ambient><diffuse>0.55 0.16 0.65 1.00</diffuse><specular>0.1 0.1 0.1 1.00</specular></material>
<geometry><mesh><uri>model://rg_robot/meshes/ActiveHinge_Frame.dae</uri></mesh></geometry></visual>
<collision name="component_node-17__frame_collision"><pose>3.052499e-03 2.911475e-02 -2.465428e-17 3.141593e+00 9.224219e-16 1.671400e+00</pose>
<surface><contact><ode><kd>3.333333e+06</kd><kp>9.000000e+04</kp></ode></contact>
<friction><ode><mu>1.000000e+00</mu>
<mu2>1.000000e+00</mu2>
<slip1>1.000000e-02</slip1>
<slip2>1.000000e-02</slip2></ode>
<bullet><friction>1.000000e+00</friction>
<friction2>1.000000e+00</friction2></bullet></friction></surface>
<geometry><box><size>1.800000e-02 3.400000e-02 1.000000e-02</size></box></geometry></collision>
<inertial><mass>4.560000e-02</mass><inertia><ixx>1.344163e-05</ixx><ixy>-1.617696e-06</ixy><ixz>-4.903727e-21</ixz><iyy>2.266898e-05</iyy><iyz>5.150799e-21</iyz><izz>2.913499e-05</izz></inertia></inertial>
<self_collide>True</self_collide></link>
<link name="link_component_node-15__servo"><pose>4.809524e-01 -1.265550e-02 8.774783e-17 0.000000e+00 -0.000000e+00 0.000000e+00</pose>
<visual name="component_node-15__servo_servo_visual"><pose>-5.702271e-03 -5.756141e-04 -1.352130e-18 -1.570796e+00 -2.359224e-16 1.006039e-01</pose>
<material><ambient>0.84 0.05 0.24 1.00</ambient><diffuse>0.84 0.05 0.24 1.00</diffuse><specular>0.1 0.1 0.1 1.00</specular></material>
<geometry><mesh><uri>model://rg_robot/meshes/ActiveCardanHinge_Servo_Holder.dae</uri></mesh></geometry></visual>
<collision name="component_node-15__servo_collision"><pose>-5.702271e-03 -5.756141e-04 -1.352130e-18 -1.570796e+00 -2.359224e-16 1.006039e-01</pose>
<surface><contact><ode><kd>3.333333e+06</kd><kp>9.000000e+04</kp></ode></contact>
<friction><ode><mu>1.000000e+00</mu>
<mu2>1.000000e+00</mu2>
<slip1>1.000000e-02</slip1>
<slip2>1.000000e-02</slip2></ode>
<bullet><friction>1.000000e+00</friction>
<friction2>1.000000e+00</friction2></bullet></friction></surface>
<geometry><box><size>2.450000e-02 3.400000e-02 1.000000e-02</size></box></geometry></collision>
<collision name="component_node-15__tail_collision"><pose>7.331491e-03 7.400753e-04 1.738453e-18 -1.570796e+00 -2.359224e-16 1.006039e-01</pose>
<surface><contact><ode><kd>3.333333e+06</kd><kp>9.000000e+04</kp></ode></contact>
<friction><ode><mu>1.000000e+00</mu>
<mu2>1.000000e+00</mu2>
<slip1>1.000000e-02</slip1>
<slip2>1.000000e-02</slip2></ode>
<bullet><friction>1.000000e+00</friction>
<friction2>1.000000e+00</friction2></bullet></friction></surface>
<geometry><box><size>1.500000e-03 3.400000e-02 3.400000e-02</size></box></geometry></collision>
<inertial><mass>1.600000e-02</mass><inertia><ixx>2.294478e-06</ixx><ixy>-3.776032e-08</ixy><ixz>1.489021e-22</ixz><iyy>2.664736e-06</iyy><iyz>-7.255453e-22</iyz><izz>1.876548e-06</izz></inertia></inertial>
<self_collide>True</self_collide></link>
<joint type="revolute" name="joint_link_component_node-15__servo_link_component_node-13__servo"><pose>4.209347e-02 1.797683e-03 1.394778e-17 -1.570796e+00 -2.359224e-16 1.006039e-01</pose>
<parent>link_component_node-15__servo</parent>
<child>link_component_node-13__servo</child>
<axis><xyz>0.000000e+00 1.000000e+00 0.000000e+00</xyz>
<use_parent_model_frame>0</use_parent_model_frame>
<limit><lower>-7.853982e-01</lower>
<upper>7.853982e-01</upper>
<effort>1.765800e-01</effort>
<velocity>5.235988e+00</velocity></limit></axis></joint>
<link name="link_component_node-16__conn_a"><pose>4.367738e-01 -7.365096e-02 1.410728e-16 0.000000e+00 -0.000000e+00 0.000000e+00</pose>
<visual name="component_node-16__conn_a_conn_a_visual"><pose>-6.678881e-04 6.616376e-03 -8.962462e-18 -1.570796e+00 1.332268e-15 1.671400e+00</pose>
<material><ambient>0.55 0.16 0.65 1.00</ambient><diffuse>0.55 0.16 0.65 1.00</diffuse><specular>0.1 0.1 0.1 1.00</specular></material>
<geometry><mesh><uri>model://rg_robot/meshes/PassiveHinge.dae</uri></mesh></geometry></visual>
<collision name="component_node-16__conn_a_collision"><pose>-7.432138e-04 7.362583e-03 -9.858780e-18 -1.570796e+00 1.332268e-15 1.671400e+00</pose>
<surface><contact><ode><kd>3.333333e+06</kd><kp>9.000000e+04</kp></ode></contact>
<friction><ode><mu>1.000000e+00</mu>
<mu2>1.000000e+00</mu2>
<slip1>1.000000e-02</slip1>
<slip2>1.000000e-02</slip2></ode>
<bullet><friction>1.000000e+00</friction>
<friction2>1.000000e+00</friction2></bullet></friction></surface>
<geometry><box><size>2.050000e-02 2.000000e-03 2.000000e-02</size></box></geometry></collision>
<collision name="component_node-16__slot_a_collision"><pose>3.716069e-04 -3.681292e-03 4.929390e-18 -1.570796e+00 1.332268e-15 1.671400e+00</pose>
<surface><contact><ode><kd>3.333333e+06</kd><kp>9.000000e+04</kp></ode></contact>
<friction><ode><mu>1.000000e+00</mu>
<mu2>1.000000e+00</mu2>
<slip1>1.000000e-02</slip1>
<slip2>1.000000e-02</slip2></ode>
<bullet><friction>1.000000e+00</friction>
<friction2>1.000000e+00</friction2></bullet></friction></surface>
<geometry><box><size>1.500000e-03 3.400000e-02 3.400000e-02</size></box></geometry></collision>
<inertial><mass>3.000000e-03</mass><inertia><ixx>3.116299e-07</ixx><ixy>-1.083844e-08</ixy><ixz>8.469011e-24</ixz><iyy>4.179059e-07</iyy><iyz>-6.415506e-23</iyz><izz>3.435358e-07</izz></inertia></inertial>
<self_collide>True</self_collide></link>
<joint type="revolute" name="joint_link_component_node-16__conn_a_link_component_node-13__servo"><pose>1.025364e-02 -4.222271e-02 4.972127e-17 -1.570796e+00 1.332268e-15 1.671400e+00</pose>
<parent>link_component_node-16__conn_a</parent>
<child>link_component_node-13__servo</child>
<axis><xyz>0.000000e+00 0.000000e+00 1.000000e+00</xyz>
<use_parent_model_frame>0</use_parent_model_frame>
<limit><lower>-1.047198e+00</lower>
<upper>1.047198e+00</upper></limit></axis></joint>
<link name="link_component_node-17__servo"><pose>4.258952e-01 3.411715e-02 2.664905e-17 0.000000e+00 -0.000000e+00 0.000000e+00</pose>
<visual name="component_node-17__servo_servo_visual"><pose>7.749299e-04 -7.676776e-03 6.976141e-18 3.141593e+00 9.224219e-16 1.671400e+00</pose>
<material><ambient>0.55 0.16 0.65 1.00</ambient><diffuse>0.55 0.16 0.65 1.00</diffuse><specular>0.1 0.1 0.1 1.00</specular></material>
<geometry><mesh><uri>model://rg_robot/meshes/ActiveCardanHinge_Servo_Holder.dae</uri></mesh></geometry></visual>
<collision name="component_node-17__servo_collision"><pose>7.749299e-04 -7.676776e-03 6.976141e-18 3.141593e+00 9.224219e-16 1.671400e+00</pose>
<surface><contact><ode><kd>3.333333e+06</kd><kp>9.000000e+04</kp></ode></contact>
<friction><ode><mu>1.000000e+00</mu>
<mu2>1.000000e+00</mu2>
<slip1>1.000000e-02</slip1>
<slip2>1.000000e-02</slip2></ode>
<bullet><friction>1.000000e+00</friction>
<friction2>1.000000e+00</friction2></bullet></friction></surface>
<geometry><box><size>2.450000e-02 3.400000e-02 1.000000e-02</size></box></geometry></collision>
<collision name="component_node-17__tail_collision"><pose>-5.407594e-04 5.356986e-03 -5.107586e-18 3.141593e+00 9.224219e-16 1.671400e+00</pose>
<surface><contact><ode><kd>3.333333e+06</kd><kp>9.000000e+04</kp></ode></contact>
<friction><ode><mu>1.000000e+00</mu>
<mu2>1.000000e+00</mu2>
<slip1>1.000000e-02</slip1>
<slip2>1.000000e-02</slip2></ode>
<bullet><friction>1.000000e+00</friction>
<friction2>1.000000e+00</friction2></bullet></friction></surface>
<geometry><box><size>1.500000e-03 3.400000e-02 3.400000e-02</size></box></geometry></collision>
<collision name="component_node-18__slot_b_collision"><pose>-6.914109e-04 6.849402e-03 -6.340636e-18 -1.570796e+00 -8.326673e-16 -1.470192e+00</pose>
<surface><contact><ode><kd>3.333333e+06</kd><kp>9.000000e+04</kp></ode></contact>
<friction><ode><mu>1.000000e+00</mu>
<mu2>1.000000e+00</mu2>
<slip1>1.000000e-02</slip1>
<slip2>1.000000e-02</slip2></ode>
<bullet><friction>1.000000e+00</friction>
<friction2>1.000000e+00</friction2></bullet></friction></surface>
<geometry><box><size>1.500000e-03 3.400000e-02 3.400000e-02</size></box></geometry></collision>
<visual name="component_node-18__conn_b_conn_b_visual"><pose>-1.806232e-03 1.789328e-02 -1.435090e-17 -1.570796e+00 9.436896e-16 1.671400e+00</pose>
<material><ambient>0.55 0.16 0.65 1.00</ambient><diffuse>0.55 0.16 0.65 1.00</diffuse><specular>0.1 0.1 0.1 1.00</specular></material>
<geometry><mesh><uri>model://rg_robot/meshes/PassiveHinge.dae</uri></mesh></geometry></visual>
<collision name="component_node-18__conn_b_collision"><pose>-1.806232e-03 1.789328e-02 -1.435090e-17 -1.570796e+00 -8.326673e-16 -1.470192e+00</pose>
<surface><contact><ode><kd>3.333333e+06</kd><kp>9.000000e+04</kp></ode></contact>
<friction><ode><mu>1.000000e+00</mu>
<mu2>1.000000e+00</mu2>
<slip1>1.000000e-02</slip1>
<slip2>1.000000e-02</slip2></ode>
<bullet><friction>1.000000e+00</friction>
<friction2>1.000000e+00</friction2></bullet></friction></surface>
<geometry><box><size>2.050000e-02 2.000000e-03 2.000000e-02</size></box></geometry></collision>
<inertial><mass>1.900000e-02</mass><inertia><ixx>2.587420e-06</ixx><ixy>-1.234014e-08</ixy><ixz>-4.588763e-22</ixz><iyy>2.708421e-06</iyy><iyz>6.259970e-22</iyz><izz>3.411174e-06</izz></inertia></inertial>
<self_collide>True</self_collide></link>
<link name="link_component_node-18__conn_a"><pose>4.216886e-01 7.578958e-02 -4.949160e-18 0.000000e+00 -0.000000e+00 0.000000e+00</pose>
<visual name="component_node-18__conn_a_conn_a_visual"><pose>6.678881e-04 -6.616376e-03 4.834226e-18 -1.570796e+00 -8.326673e-16 -1.470192e+00</pose>
<material><ambient>0.55 0.16 0.65 1.00</ambient><diffuse>0.55 0.16 0.65 1.00</diffuse><specular>0.1 0.1 0.1 1.00</specular></material>
<geometry><mesh><uri>model://rg_robot/meshes/PassiveHinge.dae</uri></mesh></geometry></visual>
<collision name="component_node-18__conn_a_collision"><pose>7.432138e-04 -7.362583e-03 5.340173e-18 -1.570796e+00 -8.326673e-16 -1.470192e+00</pose>
<surface><contact><ode><kd>3.333333e+06</kd><kp>9.000000e+04</kp></ode></contact>
<friction><ode><mu>1.000000e+00</mu>
<mu2>1.000000e+00</mu2>
<slip1>1.000000e-02</slip1>
<slip2>1.000000e-02</slip2></ode>
<bullet><friction>1.000000e+00</friction>
<friction2>1.000000e+00</friction2></bullet></friction></surface>
<geometry><box><size>2.050000e-02 2.000000e-03 2.000000e-02</size></box></geometry></collision>
<collision name="component_node-18__slot_a_collision"><pose>-3.716069e-04 3.681292e-03 -2.670086e-18 -1.570796e+00 -8.326673e-16 -1.470192e+00</pose>
<surface><contact><ode><kd>3.333333e+06</kd><kp>9.000000e+04</kp></ode></contact>
<friction><ode><mu>1.000000e+00</mu>
<mu2>1.000000e+00</mu2>
<slip1>1.000000e-02</slip1>
<slip2>1.000000e-02</slip2></ode>
<bullet><friction>1.000000e+00</friction>
<friction2>1.000000e+00</friction2></bullet></friction></surface>
<geometry><box><size>1.500000e-03 3.400000e-02 3.400000e-02</size></box></geometry></collision>
<inertial><mass>3.000000e-03</mass><inertia><ixx>3.116299e-07</ixx><ixy>-1.083844e-08</ixy><ixz>-5.360226e-23</ixz><iyy>4.179059e-07</iyy><iyz>-2.491713e-23</iyz><izz>3.435358e-07</izz></inertia></inertial>
<self_collide>True</self_collide></link>
<joint type="revolute" name="joint_link_component_node-18__conn_a_link_component_node-17__servo"><pose>-2.634815e-03 2.610156e-02 -2.030447e-17 -1.570796e+00 -7.216450e-16 -1.470192e+00</pose>
<parent>link_component_node-18__conn_a</parent>
<child>link_component_node-17__servo</child>
<axis><xyz>0.000000e+00 0.000000e+00 1.000000e+00</xyz>
<use_parent_model_frame>0</use_parent_model_frame>
<limit><lower>-1.047198e+00</lower>
<upper>1.047198e+00</upper></limit></axis></joint>
<joint type="revolute" name="joint_link_component_node-17__servo_link_component_node-13__servo"><pose>2.550327e-03 3.408947e-02 -2.926639e-17 3.141593e+00 9.224219e-16 1.671400e+00</pose>
<parent>link_component_node-17__servo</parent>
<child>link_component_node-13__servo</child>
<axis><xyz>0.000000e+00 1.000000e+00 0.000000e+00</xyz>
<use_parent_model_frame>0</use_parent_model_frame>
<limit><lower>-7.853982e-01</lower>
<upper>7.853982e-01</upper>
<effort>1.765800e-01</effort>
<velocity>5.235988e+00</velocity></limit></axis></joint>
<joint type="revolute" name="joint_link_component_node-13__servo_link_component_node-11__servo"><pose>5.869419e-02 9.596632e-03 1.709649e-17 3.141593e+00 -3.263888e-16 1.006039e-01</pose>
<parent>link_component_node-13__servo</parent>
<child>link_component_node-11__servo</child>
<axis><xyz>0.000000e+00 1.000000e+00 0.000000e+00</xyz>
<use_parent_model_frame>0</use_parent_model_frame>
<limit><lower>-7.853982e-01</lower>
<upper>7.853982e-01</upper>
<effort>1.765800e-01</effort>
<velocity>5.235988e+00</velocity></limit></axis></joint>
<joint type="revolute" name="joint_link_component_node-11__servo_link_component_node-10__servo"><pose>1.281732e-02 1.564530e-02 -1.639146e-18 -1.570796e+00 5.551115e-17 8.844309e-01</pose>
<parent>link_component_node-11__servo</parent>
<child>link_component_node-10__servo</child>
<axis><xyz>0.000000e+00 1.000000e+00 0.000000e+00</xyz>
<use_parent_model_frame>0</use_parent_model_frame>
<limit><lower>-7.853982e-01</lower>
<upper>7.853982e-01</upper>
<effort>1.765800e-01</effort>
<velocity>5.235988e+00</velocity></limit></axis></joint>
<joint type="revolute" name="joint_link_component_node-10__servo_link_component_node-7__servo"><pose>4.829417e-02 4.082437e-03 5.480553e-18 1.570796e+00 -1.110223e-16 8.844309e-01</pose>
<parent>link_component_node-10__servo</parent>
<child>link_component_node-7__servo</child>
<axis><xyz>0.000000e+00 1.000000e+00 0.000000e+00</xyz>
<use_parent_model_frame>0</use_parent_model_frame>
<limit><lower>-7.853982e-01</lower>
<upper>7.853982e-01</upper>
<effort>1.765800e-01</effort>
<velocity>5.235988e+00</velocity></limit></axis></joint>
<link name="link_component_node-19__conn_a"><pose>1.787198e-01 -1.256327e-01 5.866461e-17 0.000000e+00 -0.000000e+00 0.000000e+00</pose>
<visual name="component_node-19__conn_a_conn_a_visual"><pose>7.034401e-03 8.586454e-03 -4.950112e-18 3.141593e+00 4.603410e-16 8.844309e-01</pose>
<material><ambient>0.30 0.59 0.04 1.00</ambient><diffuse>0.30 0.59 0.04 1.00</diffuse><specular>0.1 0.1 0.1 1.00</specular></material>
<geometry><mesh><uri>model://rg_robot/meshes/PassiveHinge.dae</uri></mesh></geometry></visual>
<collision name="component_node-19__conn_a_collision"><pose>7.509699e-03 9.166620e-03 -5.295368e-18 3.141593e+00 4.603410e-16 8.844309e-01</pose>
<surface><contact><ode><kd>3.333333e+06</kd><kp>9.000000e+04</kp></ode></contact>
<friction><ode><mu>1.000000e+00</mu>
<mu2>1.000000e+00</mu2>
<slip1>1.000000e-02</slip1>
<slip2>1.000000e-02</slip2></ode>
<bullet><friction>1.000000e+00</friction>
<friction2>1.000000e+00</friction2></bullet></friction></surface>
<geometry><box><size>2.050000e-02 2.000000e-03 2.000000e-02</size></box></geometry></collision>
<collision name="component_node-19__slot_a_collision"><pose>4.752974e-04 5.801658e-04 -1.855833e-19 3.141593e+00 4.603410e-16 8.844309e-01</pose>
<surface><contact><ode><kd>3.333333e+06</kd><kp>9.000000e+04</kp></ode></contact>
<friction><ode><mu>1.000000e+00</mu>
<mu2>1.000000e+00</mu2>
<slip1>1.000000e-02</slip1>
<slip2>1.000000e-02</slip2></ode>
<bullet><friction>1.000000e+00</friction>
<friction2>1.000000e+00</friction2></bullet></friction></surface>
<geometry><box><size>1.500000e-03 3.400000e-02 3.400000e-02</size></box></geometry></collision>
<collision name="component_node-20__slot_b_collision"><pose>-4.752974e-04 -5.801658e-04 4.511060e-19 1.570796e+00 4.440892e-16 8.844309e-01</pose>
<surface><contact><ode><kd>3.333333e+06</kd><kp>9.000000e+04</kp></ode></contact>
<friction><ode><mu>1.000000e+00</mu>
<mu2>1.000000e+00</mu2>
<slip1>1.000000e-02</slip1>
<slip2>1.000000e-02</slip2></ode>
<bullet><friction>1.000000e+00</friction>
<friction2>1.000000e+00</friction2></bullet></friction></surface>
<geometry><box><size>1.500000e-03 3.400000e-02 3.400000e-02</size></box></geometry></collision>
<visual name="component_node-20__conn_b_conn_b_visual"><pose>-7.509699e-03 -9.166620e-03 4.764322e-18 1.570796e+00 -5.551115e-16 -2.257162e+00</pose>
<material><ambient>0.55 0.16 0.65 1.00</ambient><diffuse>0.55 0.16 0.65 1.00</diffuse><specular>0.1 0.1 0.1 1.00</specular></material>
<geometry><mesh><uri>model://rg_robot/meshes/PassiveHinge.dae</uri></mesh></geometry></visual>
<collision name="component_node-20__conn_b_collision"><pose>-7.509699e-03 -9.166620e-03 4.764322e-18 1.570796e+00 4.440892e-16 8.844309e-01</pose>
<surface><contact><ode><kd>3.333333e+06</kd><kp>9.000000e+04</kp></ode></contact>
<friction><ode><mu>1.000000e+00</mu>
<mu2>1.000000e+00</mu2>
<slip1>1.000000e-02</slip1>
<slip2>1.000000e-02</slip2></ode>
<bullet><friction>1.000000e+00</friction>
<friction2>1.000000e+00</friction2></bullet></friction></surface>
<geometry><box><size>2.050000e-02 2.000000e-03 2.000000e-02</size></box></geometry></collision>
<inertial><mass>6.000000e-03</mass><inertia><ixx>7.990371e-07</ixx><ixy>3.192015e-08</ixy><ixz>1.315493e-23</ixz><iyy>8.118496e-07</iyy><iyz>-2.200238e-23</iyz><izz>7.728867e-07</izz></inertia></inertial>
<self_collide>True</self_collide></link>
<link name="link_component_node-20__conn_a"><pose>1.560640e-01 -1.532872e-01 7.271595e-17 0.000000e+00 -0.000000e+00 0.000000e+00</pose>
<visual name="component_node-20__conn_a_conn_a_visual"><pose>4.214304e-03 5.144137e-03 -2.424532e-18 1.570796e+00 4.440892e-16 8.844309e-01</pose>
<material><ambient>0.55 0.16 0.65 1.00</ambient><diffuse>0.55 0.16 0.65 1.00</diffuse><specular>0.1 0.1 0.1 1.00</specular></material>
<geometry><mesh><uri>model://rg_robot/meshes/PassiveHinge.dae</uri></mesh></geometry></visual>
<collision name="component_node-20__conn_a_collision"><pose>4.689601e-03 5.724303e-03 -2.875478e-18 1.570796e+00 4.440892e-16 8.844309e-01</pose>
<surface><contact><ode><kd>3.333333e+06</kd><kp>9.000000e+04</kp></ode></contact>
<friction><ode><mu>1.000000e+00</mu>
<mu2>1.000000e+00</mu2>
<slip1>1.000000e-02</slip1>
<slip2>1.000000e-02</slip2></ode>
<bullet><friction>1.000000e+00</friction>
<friction2>1.000000e+00</friction2></bullet></friction></surface>
<geometry><box><size>2.050000e-02 2.000000e-03 2.000000e-02</size></box></geometry></collision>
<collision name="component_node-20__slot_a_collision"><pose>-2.344800e-03 -2.862151e-03 1.437739e-18 1.570796e+00 4.440892e-16 8.844309e-01</pose>
<surface><contact><ode><kd>3.333333e+06</kd><kp>9.000000e+04</kp></ode></contact>
<friction><ode><mu>1.000000e+00</mu>
<mu2>1.000000e+00</mu2>
<slip1>1.000000e-02</slip1>
<slip2>1.000000e-02</slip2></ode>
<bullet><friction>1.000000e+00</friction>
<friction2>1.000000e+00</friction2></bullet></friction></surface>
<geometry><box><size>1.500000e-03 3.400000e-02 3.400000e-02</size></box></geometry></collision>
<inertial><mass>3.000000e-03</mass><inertia><ixx>3.540965e-07</ixx><ixy>5.317180e-08</ixy><ixz>8.984353e-24</ixz><iyy>3.754393e-07</iyy><iyz>-1.923417e-23</iyz><izz>3.435358e-07</izz></inertia></inertial>
<self_collide>True</self_collide></link>
<joint type="revolute" name="joint_link_component_node-20__conn_a_link_component_node-19__conn_a"><pose>-1.273797e-02 -1.554844e-02 7.970091e-18 1.570796e+00 3.885781e-16 8.844309e-01</pose>
<parent>link_component_node-20__conn_a</parent>
<child>link_component_node-19__conn_a</child>
<axis><xyz>0.000000e+00 0.000000e+00 1.000000e+00</xyz>
<use_parent_model_frame>0</use_parent_model_frame>
<limit><lower>-1.047198e+00</lower>
<upper>1.047198e+00</upper></limit></axis></joint>
<joint type="revolute" name="joint_link_component_node-19__conn_a_link_component_node-7__servo"><pose>-3.202864e-02 -2.926626e-02 1.652552e-17 3.141593e+00 4.603410e-16 8.844309e-01</pose>
<parent>link_component_node-19__conn_a</parent>
<child>link_component_node-7__servo</child>
<axis><xyz>0.000000e+00 0.000000e+00 1.000000e+00</xyz>
<use_parent_model_frame>0</use_parent_model_frame>
<limit><lower>-1.047198e+00</lower>
<upper>1.047198e+00</upper></limit></axis></joint>
<joint type="revolute" name="joint_link_component_node-7__servo_link_component_node-5__servo"><pose>4.951100e-02 -3.633030e-02 1.450827e-17 3.141593e+00 -1.876656e-16 -6.863655e-01</pose>
<parent>link_component_node-7__servo</parent>
<child>link_component_node-5__servo</child>
<axis><xyz>0.000000e+00 1.000000e+00 0.000000e+00</xyz>
<use_parent_model_frame>0</use_parent_model_frame>
<limit><lower>-7.853982e-01</lower>
<upper>7.853982e-01</upper>
<effort>1.765800e-01</effort>
<velocity>5.235988e+00</velocity></limit></axis></joint>
<joint type="revolute" name="joint_link_component_node-5__servo_link_component_node-4__servo"><pose>2.022521e-02 0.000000e+00 0.000000e+00 -1.570796e+00 0.000000e+00 0.000000e+00</pose>
<parent>link_component_node-5__servo</parent>
<child>link_component_node-4__servo</child>
<axis><xyz>0.000000e+00 1.000000e+00 0.000000e+00</xyz>
<use_parent_model_frame>0</use_parent_model_frame>
<limit><lower>-7.853982e-01</lower>
<upper>7.853982e-01</upper>
<effort>1.765800e-01</effort>
<velocity>5.235988e+00</velocity></limit></axis></joint>
<joint type="revolute" name="joint_link_component_node-4__servo_link_component_node-0__box"><pose>5.847705e-02 2.122954e-03 -6.593184e-21 1.570796e+00 -0.000000e+00 0.000000e+00</pose>
<parent>link_component_node-4__servo</parent>
<child>link_component_node-0__box</child>
<axis><xyz>0.000000e+00 1.000000e+00 0.000000e+00</xyz>
<use_parent_model_frame>0</use_parent_model_frame>
<limit><lower>-7.853982e-01</lower>
<upper>7.853982e-01</upper>
<effort>1.765800e-01</effort>
<velocity>5.235988e+00</velocity></limit></axis></joint>
<link name="link_component_node-21__conn_a"><pose>-8.075000e-02 0.000000e+00 0.000000e+00 0.000000e+00 -0.000000e+00 0.000000e+00</pose>
<visual name="component_node-21__conn_a_conn_a_visual"><pose>6.650000e-03 0.000000e+00 0.000000e+00 1.570796e+00 -0.000000e+00 0.000000e+00</pose>
<material><ambient>0.55 0.16 0.65 1.00</ambient><diffuse>0.55 0.16 0.65 1.00</diffuse><specular>0.1 0.1 0.1 1.00</specular></material>
<geometry><mesh><uri>model://rg_robot/meshes/PassiveHinge.dae</uri></mesh></geometry></visual>
<collision name="component_node-21__conn_a_collision"><pose>7.400000e-03 0.000000e+00 0.000000e+00 1.570796e+00 -0.000000e+00 0.000000e+00</pose>
<surface><contact><ode><kd>3.333333e+06</kd><kp>9.000000e+04</kp></ode></contact>
<friction><ode><mu>1.000000e+00</mu>
<mu2>1.000000e+00</mu2>
<slip1>1.000000e-02</slip1>
<slip2>1.000000e-02</slip2></ode>
<bullet><friction>1.000000e+00</friction>
<friction2>1.000000e+00</friction2></bullet></friction></surface>
<geometry><box><size>2.050000e-02 2.000000e-03 2.000000e-02</size></box></geometry></collision>
<collision name="component_node-21__slot_a_collision"><pose>-3.700000e-03 0.000000e+00 0.000000e+00 1.570796e+00 -0.000000e+00 0.000000e+00</pose>
<surface><contact><ode><kd>3.333333e+06</kd><kp>9.000000e+04</kp></ode></contact>
<friction><ode><mu>1.000000e+00</mu>
<mu2>1.000000e+00</mu2>
<slip1>1.000000e-02</slip1>
<slip2>1.000000e-02</slip2></ode>
<bullet><friction>1.000000e+00</friction>
<friction2>1.000000e+00</friction2></bullet></friction></surface>
<geometry><box><size>1.500000e-03 3.400000e-02 3.400000e-02</size></box></geometry></collision>
<inertial><mass>3.000000e-03</mass><inertia><ixx>4.190000e-07</ixx><ixy>0.000000e+00</ixy><ixz>0.000000e+00</ixz><iyy>3.105358e-07</iyy><iyz>-1.465494e-23</iyz><izz>3.435358e-07</izz></inertia></inertial>
<self_collide>True</self_collide></link>
<joint type="revolute" name="joint_link_component_node-21__conn_a_link_component_node-0__box"><pose>-6.722295e-02 2.122954e-03 -6.593184e-21 1.570796e+00 -0.000000e+00 0.000000e+00</pose>
<parent>link_component_node-21__conn_a</parent>
<child>link_component_node-0__box</child>
<axis><xyz>0.000000e+00 0.000000e+00 1.000000e+00</xyz>
<use_parent_model_frame>0</use_parent_model_frame>
<limit><lower>-1.047198e+00</lower>
<upper>1.047198e+00</upper></limit></axis></joint>
<plugin name="robot_controller" filename="libtolrobotcontrol.so"><rv:robot_config xmlns:rv="https://github.com/ElteHupkes/revolve"><rv:update_rate>8.000000e+00</rv:update_rate>
<rv:brain><rv:neuron layer="input" type="Input" id="node-0-in-0" part_id="node-0" />
<rv:neuron layer="input" type="Input" id="node-0-in-1" part_id="node-0" />
<rv:neuron layer="input" type="Input" id="node-0-in-2" part_id="node-0" />
<rv:neuron layer="input" type="Input" id="node-0-in-3" part_id="node-0" />
<rv:neuron layer="input" type="Input" id="node-0-in-4" part_id="node-0" />
<rv:neuron layer="input" type="Input" id="node-0-in-5" part_id="node-0" />
<rv:neuron layer="hidden" type="Sigmoid" id="node-0-hidden-0" part_id="node-0"><rv:bias>-3.567165e-02</rv:bias>
<rv:gain>5.011507e-01</rv:gain></rv:neuron>
<rv:neuron layer="output" type="Oscillator" id="node-1-out-0" part_id="node-1"><rv:period>4.084458e+00</rv:period>
<rv:amplitude>8.414951e-01</rv:amplitude>
<rv:phase_offset>1.199118e+00</rv:phase_offset></rv:neuron>
<rv:neuron layer="output" type="Oscillator" id="node-4-out-0" part_id="node-4"><rv:period>5.468696e+00</rv:period>
<rv:amplitude>9.913937e-01</rv:amplitude>
<rv:phase_offset>1.760407e+00</rv:phase_offset></rv:neuron>
<rv:neuron layer="output" type="Oscillator" id="node-5-out-0" part_id="node-5"><rv:period>4.929424e+00</rv:period>
<rv:amplitude>1.237162e+00</rv:amplitude>
<rv:phase_offset>2.350404e+00</rv:phase_offset></rv:neuron>
<rv:neuron layer="output" type="Oscillator" id="node-7-out-0" part_id="node-7"><rv:period>5.271430e+00</rv:period>
<rv:amplitude>1.320154e+00</rv:amplitude>
<rv:phase_offset>1.433864e+00</rv:phase_offset></rv:neuron>
<rv:neuron layer="output" type="Oscillator" id="node-10-out-0" part_id="node-10"><rv:period>4.600192e+00</rv:period>
<rv:amplitude>1.001963e+00</rv:amplitude>
<rv:phase_offset>1.955982e+00</rv:phase_offset></rv:neuron>
<rv:neuron layer="output" type="Oscillator" id="node-11-out-0" part_id="node-11"><rv:period>5.356042e+00</rv:period>
<rv:amplitude>8.942967e-01</rv:amplitude>
<rv:phase_offset>2.046884e+00</rv:phase_offset></rv:neuron>
<rv:neuron layer="output" type="Oscillator" id="node-13-out-0" part_id="node-13"><rv:period>4.306032e+00</rv:period>
<rv:amplitude>9.934239e-01</rv:amplitude>
<rv:phase_offset>2.001663e+00</rv:phase_offset></rv:neuron>
<rv:neuron layer="output" type="Oscillator" id="node-15-out-0" part_id="node-15"><rv:period>4.226811e+00</rv:period>
<rv:amplitude>9.080319e-01</rv:amplitude>
<rv:phase_offset>1.387360e+00</rv:phase_offset></rv:neuron>
<rv:neuron layer="output" type="Oscillator" id="node-17-out-0" part_id="node-17"><rv:period>3.502452e+00</rv:period>
<rv:amplitude>1.066392e+00</rv:amplitude>
<rv:phase_offset>1.139868e+00</rv:phase_offset></rv:neuron>
<rv:neural_connection src="node-0-in-0" dst="node-0-hidden-0" weight="5.895497e-01" />
<rv:neural_connection src="node-0-in-2" dst="node-1-out-0" weight="5.792778e-01" />
<rv:neural_connection src="node-0-in-4" dst="node-5-out-0" weight="5.347230e-01" />
<rv:neural_connection src="node-0-in-0" dst="node-13-out-0" weight="5.145705e-01" />
<rv:neural_connection src="node-0-in-1" dst="node-1-out-0" weight="8.583960e-01" />
<rv:neural_connection src="node-1-out-0" dst="node-1-out-0" weight="8.822197e-01" />
<rv:neural_connection src="node-10-out-0" dst="node-11-out-0" weight="9.703897e-01" />
<rv:neural_connection src="node-11-out-0" dst="node-7-out-0" weight="6.865854e-02" />
<rv:neural_connection src="node-17-out-0" dst="node-17-out-0" weight="8.822197e-01" /></rv:brain>
<rv:sensor link="link_component_node-0__box" sensor="node-0-imu_sensor" type="imu" id="node-0__node-0-imu_sensor" part_id="node-0" />
<rv:motor joint="joint_link_component_node-1__servo_link_component_node-0__box" type="position" id="node-1__rotate" part_id="node-1"><rv:pid><rv:p>9.000000e-01</rv:p>
<rv:i>0.000000e+00</rv:i>
<rv:d>0.000000e+00</rv:d>
<rv:i_max>0.000000e+00</rv:i_max>
<rv:i_min>0.000000e+00</rv:i_min></rv:pid></rv:motor>
<rv:motor joint="joint_link_component_node-4__servo_link_component_node-0__box" type="position" id="node-4__rotate" part_id="node-4"><rv:pid><rv:p>9.000000e-01</rv:p>
<rv:i>0.000000e+00</rv:i>
<rv:d>0.000000e+00</rv:d>
<rv:i_max>0.000000e+00</rv:i_max>
<rv:i_min>0.000000e+00</rv:i_min></rv:pid></rv:motor>
<rv:motor joint="joint_link_component_node-5__servo_link_component_node-4__servo" type="position" id="node-5__rotate" part_id="node-5"><rv:pid><rv:p>9.000000e-01</rv:p>
<rv:i>0.000000e+00</rv:i>
<rv:d>0.000000e+00</rv:d>
<rv:i_max>0.000000e+00</rv:i_max>
<rv:i_min>0.000000e+00</rv:i_min></rv:pid></rv:motor>
<rv:motor joint="joint_link_component_node-7__servo_link_component_node-5__servo" type="position" id="node-7__rotate" part_id="node-7"><rv:pid><rv:p>9.000000e-01</rv:p>
<rv:i>0.000000e+00</rv:i>
<rv:d>0.000000e+00</rv:d>
<rv:i_max>0.000000e+00</rv:i_max>
<rv:i_min>0.000000e+00</rv:i_min></rv:pid></rv:motor>
<rv:motor joint="joint_link_component_node-10__servo_link_component_node-7__servo" type="position" id="node-10__rotate" part_id="node-10"><rv:pid><rv:p>9.000000e-01</rv:p>
<rv:i>0.000000e+00</rv:i>
<rv:d>0.000000e+00</rv:d>
<rv:i_max>0.000000e+00</rv:i_max>
<rv:i_min>0.000000e+00</rv:i_min></rv:pid></rv:motor>
<rv:motor joint="joint_link_component_node-11__servo_link_component_node-10__servo" type="position" id="node-11__rotate" part_id="node-11"><rv:pid><rv:p>9.000000e-01</rv:p>
<rv:i>0.000000e+00</rv:i>
<rv:d>0.000000e+00</rv:d>
<rv:i_max>0.000000e+00</rv:i_max>
<rv:i_min>0.000000e+00</rv:i_min></rv:pid></rv:motor>
<rv:motor joint="joint_link_component_node-13__servo_link_component_node-11__servo" type="position" id="node-13__rotate" part_id="node-13"><rv:pid><rv:p>9.000000e-01</rv:p>
<rv:i>0.000000e+00</rv:i>
<rv:d>0.000000e+00</rv:d>
<rv:i_max>0.000000e+00</rv:i_max>
<rv:i_min>0.000000e+00</rv:i_min></rv:pid></rv:motor>
<rv:motor joint="joint_link_component_node-15__servo_link_component_node-13__servo" type="position" id="node-15__rotate" part_id="node-15"><rv:pid><rv:p>9.000000e-01</rv:p>
<rv:i>0.000000e+00</rv:i>
<rv:d>0.000000e+00</rv:d>
<rv:i_max>0.000000e+00</rv:i_max>
<rv:i_min>0.000000e+00</rv:i_min></rv:pid></rv:motor>
<rv:motor joint="joint_link_component_node-17__servo_link_component_node-13__servo" type="position" id="node-17__rotate" part_id="node-17"><rv:pid><rv:p>9.000000e-01</rv:p>
<rv:i>0.000000e+00</rv:i>
<rv:d>0.000000e+00</rv:d>
<rv:i_max>0.000000e+00</rv:i_max>
<rv:i_min>0.000000e+00</rv:i_min></rv:pid></rv:motor>
<rv:battery><rv:level>0.000000e+00</rv:level></rv:battery></rv:robot_config></plugin>
<static>0</static></model></sdf>